Workbook

Sheet Summary M1 Digital
A1: BN - P&L | B1: Forecast | C1: Forecast | D1: Forecast | E1: Forecast | F1: Forecast | G1: Forecast | H1: Forecast | I1: Forecast | J1: Forecast | K1: Forecast
B2: 45992 | C2: 46023 | D2: 46054 | E2: 46082 | F2: 46113 | G2: 46143 | H2: 46174 | I2: 46204 | J2: 46235 | K2: 46266 | L2: FY26
A3: App
A4: Turnover
A5: CoS
A6: GP
A7: GP%
A9: Facebook
A10: Turnover | B10: ='Revenue - Digital'!D6 -> 6666.6667 | C10: ='Revenue - Digital'!E6 -> 8750 | D10: ='Revenue - Digital'!F6 -> 8750 | E10: ='Revenue - Digital'!G6 -> 8750 | F10: ='Revenue - Digital'!H6 -> 8750 | G10: ='Revenue - Digital'!I6 -> 8750 | H10: ='Revenue - Digital'!J6 -> 8750 | I10: ='Revenue - Digital'!K6 -> 8750 | ... K10: ='Revenue - Digital'!M6 -> 8750
A11: CoS - Staff costs | B11: =-SUMIF('M1 Staff costs'!$A:$A,'Summary M1 Digital'!$A$9,'M1 Staff costs'!I:I) -> -2831.4 | C11: =-SUMIF('M1 Staff costs'!$A:$A,'Summary M1 Digital'!$A$9,'M1 Staff costs'!J:J) -> -3425.4 | D11: =-SUMIF('M1 Staff costs'!$A:$A,'Summary M1 Digital'!$A$9,'M1 Staff costs'!K:K) -> -2831.4 | E11: =-SUMIF('M1 Staff costs'!$A:$A,'Summary M1 Digital'!$A$9,'M1 Staff costs'!L:L) -> -2587.9 | F11: =-SUMIF('M1 Staff costs'!$A:$A,'Summary M1 Digital'!$A$9,'M1 Staff costs'!M:M) -> -2439.4 | G11: =-SUMIF('M1 Staff costs'!$A:$A,'Summary M1 Digital'!$A$9,'M1 Staff costs'!N:N) -> -2439.4 | H11: =-SUMIF('M1 Staff costs'!$A:$A,'Summary M1 Digital'!$A$9,'M1 Staff costs'!O:O) -> -2439.4 | I11: =-SUMIF('M1 Staff costs'!$A:$A,'Summary M1 Digital'!$A$9,'M1 Staff costs'!P:P) -> -2439.4 | J11: =-SUMIF('M1 Staff costs'!$A:$A,'Summary M1 Digital'!$A$9,'M1 Staff costs'!Q:Q) -> -2439.4 | K11: =-SUMIF('M1 Staff costs'!$A:$A,'Summary M1 Digital'!$A$9,'M1 Staff costs'!R:R) -> -2439.4
A12: CoS - Freelancers | B12: =-SUMIF('M1 Freelancers'!$A:$A,'M1 Freelancers'!$A$5,'M1 Freelancers'!E:E) -> -300 | C12: =-SUMIF('M1 Freelancers'!$A:$A,'M1 Freelancers'!$A$5,'M1 Freelancers'!F:F) -> -300 | D12: =-SUMIF('M1 Freelancers'!$A:$A,'M1 Freelancers'!$A$5,'M1 Freelancers'!G:G) -> -300 | E12: =-SUMIF('M1 Freelancers'!$A:$A,'M1 Freelancers'!$A$5,'M1 Freelancers'!H:H) -> -300 | F12: =-SUMIF('M1 Freelancers'!$A:$A,'M1 Freelancers'!$A$5,'M1 Freelancers'!I:I) -> -300 | G12: =-SUMIF('M1 Freelancers'!$A:$A,'M1 Freelancers'!$A$5,'M1 Freelancers'!J:J) -> -300 | H12: =-SUMIF('M1 Freelancers'!$A:$A,'M1 Freelancers'!$A$5,'M1 Freelancers'!K:K) -> -300 | I12: =-SUMIF('M1 Freelancers'!$A:$A,'M1 Freelancers'!$A$5,'M1 Freelancers'!L:L) -> -300 | J12: =-SUMIF('M1 Freelancers'!$A:$A,'M1 Freelancers'!$A$5,'M1 Freelancers'!M:M) -> -300 | K12: =-SUMIF('M1 Freelancers'!$A:$A,'M1 Freelancers'!$A$5,'M1 Freelancers'!N:N) -> -300
A13: GP | B13: =SUM(B10:B12) -> 3535.2667 | C13: =SUM(C10:C12) -> 5024.6 | D13: =SUM(D10:D12) -> 5618.6 | E13: =SUM(E10:E12) -> 5862.1 | F13: =SUM(F10:F12) -> 6010.6 | G13: =SUM(G10:G12) -> 6010.6 | H13: =SUM(H10:H12) -> 6010.6 | I13: =SUM(I10:I12) -> 6010.6 | ... K13: =SUM(K10:K12) -> 6010.6
A14: Other Op costs | B14: =-SUMIF(OH!$A:$A,'Summary M1 Digital'!$A$9,OH!E:E) -> -1029.2 | C14: =-SUMIF(OH!$A:$A,'Summary M1 Digital'!$A$9,OH!F:F) -> -1029.2 | D14: =-SUMIF(OH!$A:$A,'Summary M1 Digital'!$A$9,OH!G:G) -> -862.53333 | E14: =-SUMIF(OH!$A:$A,'Summary M1 Digital'!$A$9,OH!H:H) -> -862.53333 | F14: =-SUMIF(OH!$A:$A,'Summary M1 Digital'!$A$9,OH!I:I) -> -862.53333 | G14: =-SUMIF(OH!$A:$A,'Summary M1 Digital'!$A$9,OH!J:J) -> -862.53333 | H14: =-SUMIF(OH!$A:$A,'Summary M1 Digital'!$A$9,OH!K:K) -> -862.53333 | I14: =-SUMIF(OH!$A:$A,'Summary M1 Digital'!$A$9,OH!L:L) -> -862.53333 | J14: =-SUMIF(OH!$A:$A,'Summary M1 Digital'!$A$9,OH!M:M) -> -862.53333 | K14: =-SUMIF(OH!$A:$A,'Summary M1 Digital'!$A$9,OH!N:N) -> -862.53333
A15: Contribution | B15: =SUM(B13:B14) -> 2506.0667 | C15: =SUM(C13:C14) -> 3995.4 | D15: =SUM(D13:D14) -> 4756.0667 | E15: =SUM(E13:E14) -> 4999.5667 | F15: =SUM(F13:F14) -> 5148.0667 | G15: =SUM(G13:G14) -> 5148.0667 | H15: =SUM(H13:H14) -> 5148.0667 | I15: =SUM(I13:I14) -> 5148.0667 | ... K15: =SUM(K13:K14) -> 5148.0667
A18: Magazine
A19: Turnover
A20: CoS - Staff costs
A21: CoS - Freelancers
A22: GP
A23: Other Op costs
A24: Contribution
A26: Website
A27: Turnover | B27: ='Revenue - Digital'!D10 -> 18900 | C27: ='Revenue - Digital'!E10 -> 3000 | D27: ='Revenue - Digital'!F10 -> 3000 | E27: ='Revenue - Digital'!G10 -> 3000 | F27: ='Revenue - Digital'!H10 -> 3000 | G27: ='Revenue - Digital'!I10 -> 3000 | H27: ='Revenue - Digital'!J10 -> 3000 | I27: ='Revenue - Digital'!K10 -> 3000 | ... K27: ='Revenue - Digital'!M10 -> 3000
A28: CoS - Staff costs | B28: =-SUMIF('M1 Staff costs'!$A:$A,$A$26,'M1 Staff costs'!I:I) -> -2481.831 | C28: =-SUMIF('M1 Staff costs'!$A:$A,$A$26,'M1 Staff costs'!J:J) -> -2481.831 | D28: =-SUMIF('M1 Staff costs'!$A:$A,$A$26,'M1 Staff costs'!K:K) -> -1763.1863 | E28: =-SUMIF('M1 Staff costs'!$A:$A,$A$26,'M1 Staff costs'!L:L) -> 0 | F28: =-SUMIF('M1 Staff costs'!$A:$A,$A$26,'M1 Staff costs'!M:M) -> 0 | G28: =-SUMIF('M1 Staff costs'!$A:$A,$A$26,'M1 Staff costs'!N:N) -> 0 | H28: =-SUMIF('M1 Staff costs'!$A:$A,$A$26,'M1 Staff costs'!O:O) -> 0 | I28: =-SUMIF('M1 Staff costs'!$A:$A,$A$26,'M1 Staff costs'!P:P) -> 0 | J28: =-SUMIF('M1 Staff costs'!$A:$A,$A$26,'M1 Staff costs'!Q:Q) -> 0 | K28: =-SUMIF('M1 Staff costs'!$A:$A,$A$26,'M1 Staff costs'!R:R) -> 0
A29: CoS - Freelancers
A30: GP | B30: =SUM(B27:B29) -> 16418.169 | C30: =SUM(C27:C29) -> 518.169 | D30: =SUM(D27:D29) -> 1236.8137 | E30: =SUM(E27:E29) -> 3000 | F30: =SUM(F27:F29) -> 3000 | G30: =SUM(G27:G29) -> 3000 | H30: =SUM(H27:H29) -> 3000 | I30: =SUM(I27:I29) -> 3000 | ... K30: =SUM(K27:K29) -> 3000
A31: Other Op costs | B31: =-SUMIF(OH!$A:$A,$A$26,OH!E:E) -> 0 | C31: =-SUMIF(OH!$A:$A,$A$26,OH!F:F) -> 0 | D31: =-SUMIF(OH!$A:$A,$A$26,OH!G:G) -> 0 | E31: =-SUMIF(OH!$A:$A,$A$26,OH!H:H) -> 0 | F31: =-SUMIF(OH!$A:$A,$A$26,OH!I:I) -> 0 | G31: =-SUMIF(OH!$A:$A,$A$26,OH!J:J) -> 0 | H31: =-SUMIF(OH!$A:$A,$A$26,OH!K:K) -> 0 | I31: =-SUMIF(OH!$A:$A,$A$26,OH!L:L) -> 0 | J31: =-SUMIF(OH!$A:$A,$A$26,OH!M:M) -> 0 | K31: =-SUMIF(OH!$A:$A,$A$26,OH!N:N) -> 0
A32: Contribution | B32: =SUM(B30:B31) -> 16418.169 | C32: =SUM(C30:C31) -> 518.169 | D32: =SUM(D30:D31) -> 1236.8137 | E32: =SUM(E30:E31) -> 3000 | F32: =SUM(F30:F31) -> 3000 | G32: =SUM(G30:G31) -> 3000 | H32: =SUM(H30:H31) -> 3000 | I32: =SUM(I30:I31) -> 3000 | ... K32: =SUM(K30:K31) -> 3000
A35: Youtube
A36: Turnover | B36: ='Revenue - Digital'!D18 -> 1000 | C36: ='Revenue - Digital'!E18 -> 1000 | D36: ='Revenue - Digital'!F18 -> 1000 | E36: ='Revenue - Digital'!G18 -> 1000 | F36: ='Revenue - Digital'!H18 -> 1000 | G36: ='Revenue - Digital'!I18 -> 1000 | H36: ='Revenue - Digital'!J18 -> 1000 | I36: ='Revenue - Digital'!K18 -> 1000 | ... K36: ='Revenue - Digital'!M18 -> 1000
A37: CoS - Staff costs | B37: =-SUMIF('M1 Staff costs'!$A:$A,$A$35,'M1 Staff costs'!I:I) -> -4118.4 | C37: =-SUMIF('M1 Staff costs'!$A:$A,$A$35,'M1 Staff costs'!J:J) -> -4712.4 | D37: =-SUMIF('M1 Staff costs'!$A:$A,$A$35,'M1 Staff costs'!K:K) -> -4118.4 | E37: =-SUMIF('M1 Staff costs'!$A:$A,$A$35,'M1 Staff costs'!L:L) -> -3969.9 | F37: =-SUMIF('M1 Staff costs'!$A:$A,$A$35,'M1 Staff costs'!M:M) -> -3821.4 | G37: =-SUMIF('M1 Staff costs'!$A:$A,$A$35,'M1 Staff costs'!N:N) -> -3821.4 | H37: =-SUMIF('M1 Staff costs'!$A:$A,$A$35,'M1 Staff costs'!O:O) -> -3821.4 | I37: =-SUMIF('M1 Staff costs'!$A:$A,$A$35,'M1 Staff costs'!P:P) -> -3821.4 | J37: =-SUMIF('M1 Staff costs'!$A:$A,$A$35,'M1 Staff costs'!Q:Q) -> -3821.4 | K37: =-SUMIF('M1 Staff costs'!$A:$A,$A$35,'M1 Staff costs'!R:R) -> -3821.4
A38: CoS - Freelancers | B38: =-SUMIF('M1 Freelancers'!$A:$A,'M1 Freelancers'!$A$8,'M1 Freelancers'!E:E) -> -133.33333 | C38: =-SUMIF('M1 Freelancers'!$A:$A,'M1 Freelancers'!$A$8,'M1 Freelancers'!F:F) -> -133.33333 | D38: =-SUMIF('M1 Freelancers'!$A:$A,'M1 Freelancers'!$A$8,'M1 Freelancers'!G:G) -> -133.33333 | E38: =-SUMIF('M1 Freelancers'!$A:$A,'M1 Freelancers'!$A$8,'M1 Freelancers'!H:H) -> -133.33333 | F38: =-SUMIF('M1 Freelancers'!$A:$A,'M1 Freelancers'!$A$8,'M1 Freelancers'!I:I) -> -133.33333 | G38: =-SUMIF('M1 Freelancers'!$A:$A,'M1 Freelancers'!$A$8,'M1 Freelancers'!J:J) -> -133.33333 | H38: =-SUMIF('M1 Freelancers'!$A:$A,'M1 Freelancers'!$A$8,'M1 Freelancers'!K:K) -> -133.33333 | I38: =-SUMIF('M1 Freelancers'!$A:$A,'M1 Freelancers'!$A$8,'M1 Freelancers'!L:L) -> -133.33333 | J38: =-SUMIF('M1 Freelancers'!$A:$A,'M1 Freelancers'!$A$8,'M1 Freelancers'!M:M) -> -133.33333 | K38: =-SUMIF('M1 Freelancers'!$A:$A,'M1 Freelancers'!$A$8,'M1 Freelancers'!N:N) -> -133.33333
A39: GP | B39: =SUM(B36:B38) -> -3251.7333 | C39: =SUM(C36:C38) -> -3845.7333 | D39: =SUM(D36:D38) -> -3251.7333 | E39: =SUM(E36:E38) -> -3103.2333 | F39: =SUM(F36:F38) -> -2954.7333 | G39: =SUM(G36:G38) -> -2954.7333 | H39: =SUM(H36:H38) -> -2954.7333 | I39: =SUM(I36:I38) -> -2954.7333 | ... K39: =SUM(K36:K38) -> -2954.7333
A40: Other Op costs | B40: =-SUMIF(OH!$A:$A,$A$35,OH!E:E) -> -1029.2 | C40: =-SUMIF(OH!$A:$A,$A$35,OH!F:F) -> -1029.2 | D40: =-SUMIF(OH!$A:$A,$A$35,OH!G:G) -> -862.53333 | E40: =-SUMIF(OH!$A:$A,$A$35,OH!H:H) -> -862.53333 | F40: =-SUMIF(OH!$A:$A,$A$35,OH!I:I) -> -862.53333 | G40: =-SUMIF(OH!$A:$A,$A$35,OH!J:J) -> -862.53333 | H40: =-SUMIF(OH!$A:$A,$A$35,OH!K:K) -> -862.53333 | I40: =-SUMIF(OH!$A:$A,$A$35,OH!L:L) -> -862.53333 | J40: =-SUMIF(OH!$A:$A,$A$35,OH!M:M) -> -862.53333 | K40: =-SUMIF(OH!$A:$A,$A$35,OH!N:N) -> -862.53333
A41: Contribution | B41: =SUM(B39:B40) -> -4280.9333 | C41: =SUM(C39:C40) -> -4874.9333 | D41: =SUM(D39:D40) -> -4114.2667 | E41: =SUM(E39:E40) -> -3965.7667 | F41: =SUM(F39:F40) -> -3817.2667 | G41: =SUM(G39:G40) -> -3817.2667 | H41: =SUM(H39:H40) -> -3817.2667 | I41: =SUM(I39:I40) -> -3817.2667 | ... K41: =SUM(K39:K40) -> -3817.2667
A44: Instagram
A45: Turnover | B45: ='Revenue - Digital'!D24 -> 0 | C45: ='Revenue - Digital'!E24 -> 2083.3333 | D45: ='Revenue - Digital'!F24 -> 2083.3333 | E45: ='Revenue - Digital'!G24 -> 2083.3333 | F45: ='Revenue - Digital'!H24 -> 2083.3333 | G45: ='Revenue - Digital'!I24 -> 2083.3333 | H45: ='Revenue - Digital'!J24 -> 2083.3333 | I45: ='Revenue - Digital'!K24 -> 2083.3333 | ... K45: ='Revenue - Digital'!M24 -> 2083.3333
A46: CoS - Staff costs | B46: =-SUMIF('M1 Staff costs'!$A:$A,$A$44,'M1 Staff costs'!I:I) -> -2343.825 | C46: =-SUMIF('M1 Staff costs'!$A:$A,$A$44,'M1 Staff costs'!J:J) -> -2937.825 | D46: =-SUMIF('M1 Staff costs'!$A:$A,$A$44,'M1 Staff costs'!K:K) -> -2343.825 | E46: =-SUMIF('M1 Staff costs'!$A:$A,$A$44,'M1 Staff costs'!L:L) -> -2100.325 | F46: =-SUMIF('M1 Staff costs'!$A:$A,$A$44,'M1 Staff costs'!M:M) -> -1951.825 | G46: =-SUMIF('M1 Staff costs'!$A:$A,$A$44,'M1 Staff costs'!N:N) -> -1951.825 | H46: =-SUMIF('M1 Staff costs'!$A:$A,$A$44,'M1 Staff costs'!O:O) -> -1951.825 | I46: =-SUMIF('M1 Staff costs'!$A:$A,$A$44,'M1 Staff costs'!P:P) -> -1951.825 | J46: =-SUMIF('M1 Staff costs'!$A:$A,$A$44,'M1 Staff costs'!Q:Q) -> -1951.825 | K46: =-SUMIF('M1 Staff costs'!$A:$A,$A$44,'M1 Staff costs'!R:R) -> -1951.825
A47: CoS - Freelancers | B47: =-SUMIF('M1 Freelancers'!$A:$A,'M1 Freelancers'!$A$6,'M1 Freelancers'!E:E) -> -300 | C47: =-SUMIF('M1 Freelancers'!$A:$A,'M1 Freelancers'!$A$6,'M1 Freelancers'!F:F) -> -300 | D47: =-SUMIF('M1 Freelancers'!$A:$A,'M1 Freelancers'!$A$6,'M1 Freelancers'!G:G) -> -300 | E47: =-SUMIF('M1 Freelancers'!$A:$A,'M1 Freelancers'!$A$6,'M1 Freelancers'!H:H) -> -300 | F47: =-SUMIF('M1 Freelancers'!$A:$A,'M1 Freelancers'!$A$6,'M1 Freelancers'!I:I) -> -300 | G47: =-SUMIF('M1 Freelancers'!$A:$A,'M1 Freelancers'!$A$6,'M1 Freelancers'!J:J) -> -300 | H47: =-SUMIF('M1 Freelancers'!$A:$A,'M1 Freelancers'!$A$6,'M1 Freelancers'!K:K) -> -300 | I47: =-SUMIF('M1 Freelancers'!$A:$A,'M1 Freelancers'!$A$6,'M1 Freelancers'!L:L) -> -300 | J47: =-SUMIF('M1 Freelancers'!$A:$A,'M1 Freelancers'!$A$6,'M1 Freelancers'!M:M) -> -300 | K47: =-SUMIF('M1 Freelancers'!$A:$A,'M1 Freelancers'!$A$6,'M1 Freelancers'!N:N) -> -300
A48: GP | B48: =SUM(B45:B47) -> -2643.825 | C48: =SUM(C45:C47) -> -1154.4917 | D48: =SUM(D45:D47) -> -560.49167 | E48: =SUM(E45:E47) -> -316.99167 | F48: =SUM(F45:F47) -> -168.49167 | G48: =SUM(G45:G47) -> -168.49167 | H48: =SUM(H45:H47) -> -168.49167 | I48: =SUM(I45:I47) -> -168.49167 | ... K48: =SUM(K45:K47) -> -168.49167
...

Sheet Summary - Magazine M1
A1: BN - P&L | B1: Actuals | C1: Actuals | D1: Forecast | E1: Forecast | F1: Forecast | G1: Forecast | H1: Forecast | I1: Forecast | J1: Forecast | K1: Forecast | L1: Forecast | M1: Forecast
B2: 45931 | C2: 45962 | D2: 45992 | E2: 46023 | F2: 46054 | G2: 46082 | H2: 46113 | I2: 46143 | J2: 46174 | K2: 46204 | L2: 46235 | M2: 46266 | N2: FY26
A3: Subsribers | E3: 1500 | F3: 1500 | G3: 1500 | H3: 1500 | I3: 1500 | J3: 1500 | K3: 1500 | L3: 1500 | M3: 1500
A4: In shop purchases | E4: 1000 | F4: 1000 | G4: 1000 | H4: 1000 | I4: 1000 | J4: 1000 | K4: 1000 | L4: 1000 | M4: 1000
A6: Subscription price | E6: 9.99 | F6: 9.99 | G6: 9.99 | H6: 9.99 | I6: 9.99 | J6: 9.99 | K6: 9.99 | L6: 9.99 | M6: 9.99
A7: In shop price | E7: 11.99 | F7: 11.99 | G7: 11.99 | H7: 11.99 | I7: 11.99 | J7: 11.99 | K7: 11.99 | L7: 11.99 | M7: 11.99
A8: Commission | E8: 0.35 | F8: 0.35 | G8: 0.35 | H8: 0.35 | I8: 0.35 | J8: 0.35 | K8: 0.35 | L8: 0.35 | M8: 0.35
A10: Subscription | E10: =E3*E6 -> 14985 | F10: =F3*F6 -> 14985 | G10: =G3*G6 -> 14985 | H10: =H3*H6 -> 14985 | I10: =I3*I6 -> 14985 | J10: =J3*J6 -> 14985 | K10: =K3*K6 -> 14985 | L10: =L3*L6 -> 14985 | M10: =M3*M6 -> 14985
A11: In Shop | E11: =E4*SUM(E7*E8) -> 4196.5 | F11: =F4*SUM(F7*F8) -> 4196.5 | G11: =G4*SUM(G7*G8) -> 4196.5 | H11: =H4*SUM(H7*H8) -> 4196.5 | I11: =I4*SUM(I7*I8) -> 4196.5 | J11: =J4*SUM(J7*J8) -> 4196.5 | K11: =K4*SUM(K7*K8) -> 4196.5 | L11: =L4*SUM(L7*L8) -> 4196.5 | M11: =M4*SUM(M7*M8) -> 4196.5
A13: Total | B13: =SUM(B11:B12) -> 0 | C13: =SUM(C11:C12) -> 0 | E13: =SUM(E10:E11) -> 19181.5 | F13: =SUM(F10:F11) -> 19181.5 | G13: =SUM(G10:G11) -> 19181.5 | H13: =SUM(H10:H11) -> 19181.5 | I13: =SUM(I10:I11) -> 19181.5 | J13: =SUM(J10:J11) -> 19181.5 | K13: =SUM(K10:K11) -> 19181.5 | L13: =SUM(L10:L11) -> 19181.5 | M13: =SUM(M10:M11) -> 19181.5
A15: Other Income
A16: Sponsorship | E16: 500 | F16: 500 | G16: 500 | H16: 500 | I16: 500 | J16: 500 | K16: 500 | L16: 500 | M16: 500
A17: Apple | E17: 300 | F17: 300 | G17: 300 | H17: 300 | I17: 300 | J17: 300 | K17: 300 | L17: 300 | M17: 300
A18: Jellfish | E18: 250 | F18: 250 | G18: 250 | H18: 250 | I18: 250 | J18: 250 | K18: 250 | L18: 250 | M18: 250
A19: Isubscribe / Bolin | E19: 110 | F19: 110 | G19: 110 | H19: 110 | I19: 110 | J19: 110 | K19: 110 | L19: 110 | M19: 110
A22: Total Revenue | B22: =B13+#REF!+#REF!+#REF! -> #REF! | C22: =C13+#REF!+#REF!+#REF! -> #REF! | D22: =D13 -> 0 | E22: =E13+SUM(E16:E19) -> 20341.5 | F22: =F13+SUM(F16:F19) -> 20341.5 | G22: =G13+SUM(G16:G19) -> 20341.5 | H22: =H13+SUM(H16:H19) -> 20341.5 | I22: =I13+SUM(I16:I19) -> 20341.5 | J22: =J13+SUM(J16:J19) -> 20341.5 | K22: =K13+SUM(K16:K19) -> 20341.5 | L22: =L13+SUM(L16:L19) -> 20341.5 | M22: =M13+SUM(M16:M19) -> 20341.5
A25: Costs
A26: Oliver Fennell | D26: -3200 | E26: -3200 | F26: -3200 | G26: -3200 | H26: -3200 | I26: -3200 | J26: -3200 | K26: -3200 | L26: -3200 | M26: -3200
A27: Freelancers - other | D27: -2161 | E27: -2161 | F27: -2161 | G27: -2161 | H27: -2161 | I27: -2161 | J27: -2161 | K27: -2161 | L27: -2161 | M27: -2161 | O27: Make sure to track this carefully each month
A28: Freelancers - per staff cost schedule | D28: =-SUMIF('M1 Staff costs'!$A:$A,'M1 Staff costs'!$A$5,'M1 Staff costs'!I:I) -> -6535.881 | E28: =-SUMIF('M1 Staff costs'!$A:$A,'M1 Staff costs'!$A$5,'M1 Staff costs'!J:J) -> -6595.281 | F28: =-SUMIF('M1 Staff costs'!$A:$A,'M1 Staff costs'!$A$5,'M1 Staff costs'!K:K) -> -5817.2363 | G28: =-SUMIF('M1 Staff costs'!$A:$A,'M1 Staff costs'!$A$5,'M1 Staff costs'!L:L) -> -4925.6333 | H28: =-SUMIF('M1 Staff costs'!$A:$A,'M1 Staff costs'!$A$5,'M1 Staff costs'!M:M) -> -4183.1333 | I28: =-SUMIF('M1 Staff costs'!$A:$A,'M1 Staff costs'!$A$5,'M1 Staff costs'!N:N) -> -4183.1333 | J28: =-SUMIF('M1 Staff costs'!$A:$A,'M1 Staff costs'!$A$5,'M1 Staff costs'!O:O) -> -4183.1333 | K28: =-SUMIF('M1 Staff costs'!$A:$A,'M1 Staff costs'!$A$5,'M1 Staff costs'!P:P) -> -4183.1333 | L28: =-SUMIF('M1 Staff costs'!$A:$A,'M1 Staff costs'!$A$5,'M1 Staff costs'!Q:Q) -> -4183.1333 | M28: =-SUMIF('M1 Staff costs'!$A:$A,'M1 Staff costs'!$A$5,'M1 Staff costs'!R:R) -> -4183.1333
A29: Staff costs | D29: =SUM(D26:D28) -> -11896.881 | E29: =SUM(E26:E28) -> -11956.281 | F29: =SUM(F26:F28) -> -11178.236 | G29: =SUM(G26:G28) -> -10286.633 | H29: =SUM(H26:H28) -> -9544.1333 | I29: =SUM(I26:I28) -> -9544.1333 | J29: =SUM(J26:J28) -> -9544.1333 | K29: =SUM(K26:K28) -> -9544.1333 | ... M29: =SUM(M26:M28) -> -9544.1333
A33: Monthly Print Costs | D33: -4850 | E33: -4850 | F33: -4850 | G33: -4850 | H33: -4850 | I33: -4850 | J33: -4850 | K33: -4850 | L33: -4850 | M33: -4850
A34: Monthly Mailing Fee | D34: -2000 | E34: -2000 | F34: -2000 | G34: -2000 | H34: -2000 | I34: -2000 | J34: -2000 | K34: -2000 | L34: -2000 | M34: -2000
A35: Warehouse | D35: -2240 | E35: -2240 | F35: -2240 | G35: -2240 | H35: -2240 | I35: -2240 | J35: -2240 | K35: -2240 | L35: -2240 | M35: -2240
A36: Sub's management | D36: -1056 | E36: -1056 | F36: -1056 | G36: -1056 | H36: -1056 | I36: -1056 | J36: -1056 | K36: -1056 | L36: -1056 | M36: -1056
A37: Jellyfish | D37: -300 | E37: -300 | F37: -300 | G37: -300 | H37: -300 | I37: -300 | J37: -300 | K37: -300 | L37: -300 | M37: -300
A38: Other Operating costs | D38: =-SUMIF(OH!$A:$A,OH!$A$21,OH!E:E) -> -1047.6 | E38: =-SUMIF(OH!$A:$A,OH!$A$21,OH!F:F) -> -1047.6 | F38: =-SUMIF(OH!$A:$A,OH!$A$21,OH!G:G) -> -880.93333 | G38: =-SUMIF(OH!$A:$A,OH!$A$21,OH!H:H) -> -880.93333 | H38: =-SUMIF(OH!$A:$A,OH!$A$21,OH!I:I) -> -880.93333 | I38: =-SUMIF(OH!$A:$A,OH!$A$21,OH!J:J) -> -880.93333 | J38: =-SUMIF(OH!$A:$A,OH!$A$21,OH!K:K) -> -880.93333 | K38: =-SUMIF(OH!$A:$A,OH!$A$21,OH!L:L) -> -880.93333 | L38: =-SUMIF(OH!$A:$A,OH!$A$21,OH!M:M) -> -880.93333 | M38: =-SUMIF(OH!$A:$A,OH!$A$21,OH!N:N) -> -880.93333
D39: =SUM(D33:D38) -> -11493.6 | E39: =SUM(E33:E38) -> -11493.6 | F39: =SUM(F33:F38) -> -11326.933 | G39: =SUM(G33:G38) -> -11326.933 | H39: =SUM(H33:H38) -> -11326.933 | I39: =SUM(I33:I38) -> -11326.933 | J39: =SUM(J33:J38) -> -11326.933 | K39: =SUM(K33:K38) -> -11326.933 | ... M39: =SUM(M33:M38) -> -11326.933
A42: Contribution | D42: =D22+D29+D39 -> -23390.481 | E42: =E22+E29+E39 -> -3108.381 | F42: =F22+F29+F39 -> -2163.6697 | G42: =G22+G29+G39 -> -1272.0667 | H42: =H22+H29+H39 -> -529.56667 | I42: =I22+I29+I39 -> -529.56667 | J42: =J22+J29+J39 -> -529.56667 | K42: =K22+K29+K39 -> -529.56667 | ... M42: =M22+M29+M39 -> -529.56667
D45: FY | E45: =SUM(E42:M42) -> -9721.5173

Sheet Revenue - Digital
A1: BN - P&L | B1: Actuals | C1: Actuals | D1: Forecast | E1: Forecast | F1: Forecast | G1: Forecast | H1: Forecast | I1: Forecast | J1: Forecast | K1: Forecast | L1: Forecast | M1: Forecast
B2: 45931 | C2: 45962 | D2: 45992 | E2: 46023 | F2: 46054 | G2: 46082 | H2: 46113 | I2: 46143 | J2: 46174 | K2: 46204 | L2: 46235 | M2: 46266 | N2: FY26
A3: Facebook
A4: B2B | E4: =50000/2/12 -> 2083.3333 | F4: =50000/2/12 -> 2083.3333 | G4: =50000/2/12 -> 2083.3333 | H4: =50000/2/12 -> 2083.3333 | I4: =50000/2/12 -> 2083.3333 | J4: =50000/2/12 -> 2083.3333 | K4: =50000/2/12 -> 2083.3333 | L4: =50000/2/12 -> 2083.3333 | M4: =50000/2/12 -> 2083.3333 | O4: Assumes £50k split across Facebook and Instagram
A5: PR | D5: =80000/12 -> 6666.6667 | E5: =80000/12 -> 6666.6667 | F5: =80000/12 -> 6666.6667 | G5: =80000/12 -> 6666.6667 | H5: =80000/12 -> 6666.6667 | I5: =80000/12 -> 6666.6667 | J5: =80000/12 -> 6666.6667 | K5: =80000/12 -> 6666.6667 | ... M5: =80000/12 -> 6666.6667 | O5: £80k
A6: Total | B6: =SUM(B4:B5) -> 0 | C6: =SUM(C4:C5) -> 0 | D6: =SUM(D4:D5) -> 6666.6667 | E6: =SUM(E4:E5) -> 8750 | F6: =SUM(F4:F5) -> 8750 | G6: =SUM(G4:G5) -> 8750 | H6: =SUM(H4:H5) -> 8750 | I6: =SUM(I4:I5) -> 8750 | ... M6: =SUM(M4:M5) -> 8750
A9: Website
A10: Turnover | B10: 188 | C10: 18900 | D10: 18900 | E10: 3000 | F10: 3000 | G10: 3000 | H10: 3000 | I10: 3000 | J10: 3000 | K10: 3000 | L10: 3000 | M10: 3000 | O10: Strong Nov/Dec performance
A12: Total | B12: =SUM(B10:B11) -> 188 | C12: =SUM(C10:C11) -> 18900 | D12: =SUM(D10:D11) -> 18900 | E12: =SUM(E10:E11) -> 3000 | F12: =SUM(F10:F11) -> 3000 | G12: =SUM(G10:G11) -> 3000 | H12: =SUM(H10:H11) -> 3000 | I12: =SUM(I10:I11) -> 3000 | ... M12: =SUM(M10:M11) -> 3000
A15: Youtube
A16: B2B
A17: PR | D17: 1000 | E17: 1000 | F17: 1000 | G17: 1000 | H17: 1000 | I17: 1000 | J17: 1000 | K17: 1000 | L17: 1000 | M17: 1000 | O17: In line with current performance
A18: Total | B18: =SUM(B16:B17) -> 0 | C18: =SUM(C16:C17) -> 0 | D18: =SUM(D16:D17) -> 1000 | E18: =SUM(E16:E17) -> 1000 | F18: =SUM(F16:F17) -> 1000 | G18: =SUM(G16:G17) -> 1000 | H18: =SUM(H16:H17) -> 1000 | I18: =SUM(I16:I17) -> 1000 | ... M18: =SUM(M16:M17) -> 1000
A21: Instagram
A22: B2B | E22: =50000/2/12 -> 2083.3333 | F22: =50000/2/12 -> 2083.3333 | G22: =50000/2/12 -> 2083.3333 | H22: =50000/2/12 -> 2083.3333 | I22: =50000/2/12 -> 2083.3333 | J22: =50000/2/12 -> 2083.3333 | K22: =50000/2/12 -> 2083.3333 | L22: =50000/2/12 -> 2083.3333 | M22: =50000/2/12 -> 2083.3333 | O22: Assumes £50k split across Facebook and Instagram
A23: PR
A24: Total | B24: =SUM(B22:B23) -> 0 | C24: =SUM(C22:C23) -> 0 | D24: =SUM(D22:D23) -> 0 | E24: =SUM(E22:E23) -> 2083.3333 | F24: =SUM(F22:F23) -> 2083.3333 | G24: =SUM(G22:G23) -> 2083.3333 | H24: =SUM(H22:H23) -> 2083.3333 | I24: =SUM(I22:I23) -> 2083.3333 | ... M24: =SUM(M22:M23) -> 2083.3333
A27: Total | B27: =B6+B12+B18+B24 -> 188 | C27: =C6+C12+C18+C24 -> 18900 | D27: =D6+D12+D18+D24 -> 26566.667 | E27: =E6+E12+E18+E24 -> 14833.333 | F27: =F6+F12+F18+F24 -> 14833.333 | G27: =G6+G12+G18+G24 -> 14833.333 | H27: =H6+H12+H18+H24 -> 14833.333 | I27: =I6+I12+I18+I24 -> 14833.333 | ... M27: =M6+M12+M18+M24 -> 14833.333

Sheet M1 Staff costs
C1: Current | E1: Proposed | G1: Actuals | H1: Actuals | I1: Forecast | J1: Forecast | K1: Forecast | L1: Forecast | M1: Forecast | N1: Forecast | O1: Forecast | P1: Forecast | Q1: Forecast | R1: Forecast
A2: Employee Name | B2: Allocation | C2: Gross Salary | D2: NI + Pension | E2: Bonus | F2: NI + Pension | G2: 45931 | H2: 45962 | I2: 45992 | J2: 46023 | K2: 46054 | L2: 46082 | M2: 46113 | N2: 46143 | O2: 46174 | P2: 46204 | Q2: 46235 | R2: 46266 | S2: FY26
A3: Ryan Elliot | C3: 38000 | D3: =C3*0.188 -> 7144 | E3: 2000 | F3: =E3*0.188 -> 376
A4: Facebook | B4: 0.25 | G4: =SUM($C$3:$D$3)/12*$B4 -> 940.5 | H4: =SUM($C$3:$D$3)/12*$B4 -> 940.5 | I4: =SUM($C$3:$D$3)/12*$B4 -> 940.5 | J4: =SUM($C$3:$D$3)/12*$B4+SUM($E$3:$F$3)*$B4 -> 1534.5 | K4: =SUM($C$3:$D$3)/12*$B4 -> 940.5 | L4: =SUM($C$3:$D$3)/12*$B4 -> 940.5 | M4: =SUM($C$3:$D$3)/12*$B4 -> 940.5 | N4: =SUM($C$3:$D$3)/12*$B4 -> 940.5 | O4: =SUM($C$3:$D$3)/12*$B4 -> 940.5 | P4: =SUM($C$3:$D$3)/12*$B4 -> 940.5 | Q4: =SUM($C$3:$D$3)/12*$B4 -> 940.5 | R4: =SUM($C$3:$D$3)/12*$B4 -> 940.5 | S4: =SUM(G4:R4) -> 11880
A5: Magazine | B5: 0.025 | G5: =SUM($C$3:$D$3)/12*$B5 -> 94.05 | H5: =SUM($C$3:$D$3)/12*$B5 -> 94.05 | I5: =SUM($C$3:$D$3)/12*$B5 -> 94.05 | J5: =SUM($C$3:$D$3)/12*$B5+SUM($E$3:$F$3)*$B5 -> 153.45 | K5: =SUM($C$3:$D$3)/12*$B5 -> 94.05 | L5: =SUM($C$3:$D$3)/12*$B5 -> 94.05 | M5: =SUM($C$3:$D$3)/12*$B5 -> 94.05 | N5: =SUM($C$3:$D$3)/12*$B5 -> 94.05 | O5: =SUM($C$3:$D$3)/12*$B5 -> 94.05 | P5: =SUM($C$3:$D$3)/12*$B5 -> 94.05 | Q5: =SUM($C$3:$D$3)/12*$B5 -> 94.05 | R5: =SUM($C$3:$D$3)/12*$B5 -> 94.05 | S5: =SUM(G5:R5) -> 1188
A6: Youtube | B6: 0.25 | G6: =SUM($C$3:$D$3)/12*$B6 -> 940.5 | H6: =SUM($C$3:$D$3)/12*$B6 -> 940.5 | I6: =SUM($C$3:$D$3)/12*$B6 -> 940.5 | J6: =SUM($C$3:$D$3)/12*$B6+SUM($E$3:$F$3)*$B6 -> 1534.5 | K6: =SUM($C$3:$D$3)/12*$B6 -> 940.5 | L6: =SUM($C$3:$D$3)/12*$B6 -> 940.5 | M6: =SUM($C$3:$D$3)/12*$B6 -> 940.5 | N6: =SUM($C$3:$D$3)/12*$B6 -> 940.5 | O6: =SUM($C$3:$D$3)/12*$B6 -> 940.5 | P6: =SUM($C$3:$D$3)/12*$B6 -> 940.5 | Q6: =SUM($C$3:$D$3)/12*$B6 -> 940.5 | R6: =SUM($C$3:$D$3)/12*$B6 -> 940.5 | S6: =SUM(G6:R6) -> 11880
A7: Instagram | B7: 0.25 | G7: =SUM($C$3:$D$3)/12*$B7 -> 940.5 | H7: =SUM($C$3:$D$3)/12*$B7 -> 940.5 | I7: =SUM($C$3:$D$3)/12*$B7 -> 940.5 | J7: =SUM($C$3:$D$3)/12*$B7+SUM($E$3:$F$3)*$B7 -> 1534.5 | K7: =SUM($C$3:$D$3)/12*$B7 -> 940.5 | L7: =SUM($C$3:$D$3)/12*$B7 -> 940.5 | M7: =SUM($C$3:$D$3)/12*$B7 -> 940.5 | N7: =SUM($C$3:$D$3)/12*$B7 -> 940.5 | O7: =SUM($C$3:$D$3)/12*$B7 -> 940.5 | P7: =SUM($C$3:$D$3)/12*$B7 -> 940.5 | Q7: =SUM($C$3:$D$3)/12*$B7 -> 940.5 | R7: =SUM($C$3:$D$3)/12*$B7 -> 940.5 | S7: =SUM(G7:R7) -> 11880
A8: TikTok | B8: 0.05 | G8: =SUM($C$3:$D$3)/12*$B8 -> 188.1 | H8: =SUM($C$3:$D$3)/12*$B8 -> 188.1 | I8: =SUM($C$3:$D$3)/12*$B8 -> 188.1 | J8: =SUM($C$3:$D$3)/12*$B8+SUM($E$3:$F$3)*$B8 -> 306.9 | K8: =SUM($C$3:$D$3)/12*$B8 -> 188.1 | L8: =SUM($C$3:$D$3)/12*$B8 -> 188.1 | M8: =SUM($C$3:$D$3)/12*$B8 -> 188.1 | N8: =SUM($C$3:$D$3)/12*$B8 -> 188.1 | O8: =SUM($C$3:$D$3)/12*$B8 -> 188.1 | P8: =SUM($C$3:$D$3)/12*$B8 -> 188.1 | Q8: =SUM($C$3:$D$3)/12*$B8 -> 188.1 | R8: =SUM($C$3:$D$3)/12*$B8 -> 188.1 | S8: =SUM(G8:R8) -> 2376
A9: X | B9: 0.1 | G9: =SUM($C$3:$D$3)/12*$B9 -> 376.2 | H9: =SUM($C$3:$D$3)/12*$B9 -> 376.2 | I9: =SUM($C$3:$D$3)/12*$B9 -> 376.2 | J9: =SUM($C$3:$D$3)/12*$B9+SUM($E$3:$F$3)*$B9 -> 613.8 | K9: =SUM($C$3:$D$3)/12*$B9 -> 376.2 | L9: =SUM($C$3:$D$3)/12*$B9 -> 376.2 | M9: =SUM($C$3:$D$3)/12*$B9 -> 376.2 | N9: =SUM($C$3:$D$3)/12*$B9 -> 376.2 | O9: =SUM($C$3:$D$3)/12*$B9 -> 376.2 | P9: =SUM($C$3:$D$3)/12*$B9 -> 376.2 | Q9: =SUM($C$3:$D$3)/12*$B9 -> 376.2 | R9: =SUM($C$3:$D$3)/12*$B9 -> 376.2 | S9: =SUM(G9:R9) -> 4752
A10: B2B | B10: 0.075 | G10: =SUM($C$3:$D$3)/12*$B10 -> 282.15 | H10: =SUM($C$3:$D$3)/12*$B10 -> 282.15 | I10: =SUM($C$3:$D$3)/12*$B10 -> 282.15 | J10: =SUM($C$3:$D$3)/12*$B10+SUM($E$3:$F$3)*$B10 -> 460.35 | K10: =SUM($C$3:$D$3)/12*$B10 -> 282.15 | L10: =SUM($C$3:$D$3)/12*$B10 -> 282.15 | M10: =SUM($C$3:$D$3)/12*$B10 -> 282.15 | N10: =SUM($C$3:$D$3)/12*$B10 -> 282.15 | O10: =SUM($C$3:$D$3)/12*$B10 -> 282.15 | P10: =SUM($C$3:$D$3)/12*$B10 -> 282.15 | Q10: =SUM($C$3:$D$3)/12*$B10 -> 282.15 | R10: =SUM($C$3:$D$3)/12*$B10 -> 282.15 | S10: =SUM(G10:R10) -> 3564
A12: Total | G12: =SUM(G4:G11) -> 3762 | H12: =SUM(H4:H11) -> 3762 | I12: =SUM(I4:I11) -> 3762 | J12: =SUM(J4:J11) -> 6138 | K12: =SUM(K4:K11) -> 3762 | L12: =SUM(L4:L11) -> 3762 | M12: =SUM(M4:M11) -> 3762 | N12: =SUM(N4:N11) -> 3762 | ... S12: =SUM(S4:S11) -> 47520
S13: =S12-F3-E3-D3-C3 -> 0
A14: Danny Gilfilen | C14: 25000 | D14: =C14*0.188 -> 4700
A15: Facebook | B15: 0.3 | G15: =SUM($C$14:$D$14)/12*$B15 -> 742.5 | H15: =SUM($C$14:$D$14)/12*$B15 -> 742.5 | I15: =SUM($C$14:$D$14)/12*$B15 -> 742.5 | J15: =SUM($C$14:$D$14)/12*$B15 -> 742.5 | K15: =SUM($C$14:$D$14)/12*$B15 -> 742.5 | L15: =SUM($C$14:$D$14)/12*$B15 -> 742.5 | M15: =SUM($C$14:$D$14)/12*$B15 -> 742.5 | N15: =SUM($C$14:$D$14)/12*$B15 -> 742.5 | ... R15: =SUM($C$14:$D$14)/12*$B15 -> 742.5 | S15: =SUM(G15:R15) -> 8910
A16: Magazine | B16: 0 | G16: =SUM($C$14:$D$14)/12*$B16 -> 0 | H16: =SUM($C$14:$D$14)/12*$B16 -> 0 | I16: =SUM($C$14:$D$14)/12*$B16 -> 0 | J16: =SUM($C$14:$D$14)/12*$B16 -> 0 | K16: =SUM($C$14:$D$14)/12*$B16 -> 0 | L16: =SUM($C$14:$D$14)/12*$B16 -> 0 | M16: =SUM($C$14:$D$14)/12*$B16 -> 0 | N16: =SUM($C$14:$D$14)/12*$B16 -> 0 | ... R16: =SUM($C$14:$D$14)/12*$B16 -> 0 | S16: =SUM(G16:R16) -> 0
A17: Youtube | B17: 0.3 | G17: =SUM($C$14:$D$14)/12*$B17 -> 742.5 | H17: =SUM($C$14:$D$14)/12*$B17 -> 742.5 | I17: =SUM($C$14:$D$14)/12*$B17 -> 742.5 | J17: =SUM($C$14:$D$14)/12*$B17 -> 742.5 | K17: =SUM($C$14:$D$14)/12*$B17 -> 742.5 | L17: =SUM($C$14:$D$14)/12*$B17 -> 742.5 | M17: =SUM($C$14:$D$14)/12*$B17 -> 742.5 | N17: =SUM($C$14:$D$14)/12*$B17 -> 742.5 | ... R17: =SUM($C$14:$D$14)/12*$B17 -> 742.5 | S17: =SUM(G17:R17) -> 8910
A18: Instagram | B18: 0.175 | G18: =SUM($C$14:$D$14)/12*$B18 -> 433.125 | H18: =SUM($C$14:$D$14)/12*$B18 -> 433.125 | I18: =SUM($C$14:$D$14)/12*$B18 -> 433.125 | J18: =SUM($C$14:$D$14)/12*$B18 -> 433.125 | K18: =SUM($C$14:$D$14)/12*$B18 -> 433.125 | L18: =SUM($C$14:$D$14)/12*$B18 -> 433.125 | M18: =SUM($C$14:$D$14)/12*$B18 -> 433.125 | N18: =SUM($C$14:$D$14)/12*$B18 -> 433.125 | ... R18: =SUM($C$14:$D$14)/12*$B18 -> 433.125 | S18: =SUM(G18:R18) -> 5197.5
A19: TikTok | B19: 0.175 | G19: =SUM($C$14:$D$14)/12*$B19 -> 433.125 | H19: =SUM($C$14:$D$14)/12*$B19 -> 433.125 | I19: =SUM($C$14:$D$14)/12*$B19 -> 433.125 | J19: =SUM($C$14:$D$14)/12*$B19 -> 433.125 | K19: =SUM($C$14:$D$14)/12*$B19 -> 433.125 | L19: =SUM($C$14:$D$14)/12*$B19 -> 433.125 | M19: =SUM($C$14:$D$14)/12*$B19 -> 433.125 | N19: =SUM($C$14:$D$14)/12*$B19 -> 433.125 | ... R19: =SUM($C$14:$D$14)/12*$B19 -> 433.125 | S19: =SUM(G19:R19) -> 5197.5
A20: X | B20: 0.05 | G20: =SUM($C$14:$D$14)/12*$B20 -> 123.75 | H20: =SUM($C$14:$D$14)/12*$B20 -> 123.75 | I20: =SUM($C$14:$D$14)/12*$B20 -> 123.75 | J20: =SUM($C$14:$D$14)/12*$B20 -> 123.75 | K20: =SUM($C$14:$D$14)/12*$B20 -> 123.75 | L20: =SUM($C$14:$D$14)/12*$B20 -> 123.75 | M20: =SUM($C$14:$D$14)/12*$B20 -> 123.75 | N20: =SUM($C$14:$D$14)/12*$B20 -> 123.75 | ... R20: =SUM($C$14:$D$14)/12*$B20 -> 123.75 | S20: =SUM(G20:R20) -> 1485
A21: B2B | B21: 0 | G21: =SUM($C$14:$D$14)/12*$B21 -> 0 | H21: =SUM($C$14:$D$14)/12*$B21 -> 0 | I21: =SUM($C$14:$D$14)/12*$B21 -> 0 | J21: =SUM($C$14:$D$14)/12*$B21 -> 0 | K21: =SUM($C$14:$D$14)/12*$B21 -> 0 | L21: =SUM($C$14:$D$14)/12*$B21 -> 0 | M21: =SUM($C$14:$D$14)/12*$B21 -> 0 | N21: =SUM($C$14:$D$14)/12*$B21 -> 0 | ... R21: =SUM($C$14:$D$14)/12*$B21 -> 0 | S21: =SUM(G21:R21) -> 0
A23: Total | G23: =SUM(G15:G22) -> 2475 | H23: =SUM(H15:H22) -> 2475 | I23: =SUM(I15:I22) -> 2475 | J23: =SUM(J15:J22) -> 2475 | K23: =SUM(K15:K22) -> 2475 | L23: =SUM(L15:L22) -> 2475 | M23: =SUM(M15:M22) -> 2475 | N23: =SUM(N15:N22) -> 2475 | ... S23: =SUM(S15:S22) -> 29700
S24: =S23-C14-D14 -> 0
A25: Daniel Greg | C25: 36000 | D25: =C25*0.188 -> 6768
A26: Facebook | B26: 0.1 | G26: =SUM($C$25:$D$25)/12*$B26 -> 356.4 | H26: =SUM($C$25:$D$25)/12*$B26 -> 356.4 | I26: =SUM($C$25:$D$25)/12*$B26 -> 356.4 | J26: =SUM($C$25:$D$25)/12*$B26 -> 356.4 | K26: =SUM($C$25:$D$25)/12*$B26 -> 356.4 | L26: =SUM($C$25:$D$25)/12*$B26 -> 356.4 | M26: =SUM($C$25:$D$25)/12*$B26 -> 356.4 | N26: =SUM($C$25:$D$25)/12*$B26 -> 356.4 | ... R26: =SUM($C$25:$D$25)/12*$B26 -> 356.4 | S26: =SUM(G26:R26) -> 4276.8
A27: Magazine | B27: 0 | G27: =SUM($C$25:$D$25)/12*$B27 -> 0 | H27: =SUM($C$25:$D$25)/12*$B27 -> 0 | I27: =SUM($C$25:$D$25)/12*$B27 -> 0 | J27: =SUM($C$25:$D$25)/12*$B27 -> 0 | K27: =SUM($C$25:$D$25)/12*$B27 -> 0 | L27: =SUM($C$25:$D$25)/12*$B27 -> 0 | M27: =SUM($C$25:$D$25)/12*$B27 -> 0 | N27: =SUM($C$25:$D$25)/12*$B27 -> 0 | ... R27: =SUM($C$25:$D$25)/12*$B27 -> 0 | S27: =SUM(G27:R27) -> 0
A28: Youtube | B28: 0.6 | G28: =SUM($C$25:$D$25)/12*$B28 -> 2138.4 | H28: =SUM($C$25:$D$25)/12*$B28 -> 2138.4 | I28: =SUM($C$25:$D$25)/12*$B28 -> 2138.4 | J28: =SUM($C$25:$D$25)/12*$B28 -> 2138.4 | K28: =SUM($C$25:$D$25)/12*$B28 -> 2138.4 | L28: =SUM($C$25:$D$25)/12*$B28 -> 2138.4 | M28: =SUM($C$25:$D$25)/12*$B28 -> 2138.4 | N28: =SUM($C$25:$D$25)/12*$B28 -> 2138.4 | ... R28: =SUM($C$25:$D$25)/12*$B28 -> 2138.4 | S28: =SUM(G28:R28) -> 25660.8
A29: Instagram | B29: 0.05 | G29: =SUM($C$25:$D$25)/12*$B29 -> 178.2 | H29: =SUM($C$25:$D$25)/12*$B29 -> 178.2 | I29: =SUM($C$25:$D$25)/12*$B29 -> 178.2 | J29: =SUM($C$25:$D$25)/12*$B29 -> 178.2 | K29: =SUM($C$25:$D$25)/12*$B29 -> 178.2 | L29: =SUM($C$25:$D$25)/12*$B29 -> 178.2 | M29: =SUM($C$25:$D$25)/12*$B29 -> 178.2 | N29: =SUM($C$25:$D$25)/12*$B29 -> 178.2 | ... R29: =SUM($C$25:$D$25)/12*$B29 -> 178.2 | S29: =SUM(G29:R29) -> 2138.4
A30: TikTok | B30: 0.05 | G30: =SUM($C$25:$D$25)/12*$B30 -> 178.2 | H30: =SUM($C$25:$D$25)/12*$B30 -> 178.2 | I30: =SUM($C$25:$D$25)/12*$B30 -> 178.2 | J30: =SUM($C$25:$D$25)/12*$B30 -> 178.2 | K30: =SUM($C$25:$D$25)/12*$B30 -> 178.2 | L30: =SUM($C$25:$D$25)/12*$B30 -> 178.2 | M30: =SUM($C$25:$D$25)/12*$B30 -> 178.2 | N30: =SUM($C$25:$D$25)/12*$B30 -> 178.2 | ... R30: =SUM($C$25:$D$25)/12*$B30 -> 178.2 | S30: =SUM(G30:R30) -> 2138.4
A31: X | B31: 0 | G31: =SUM($C$25:$D$25)/12*$B31 -> 0 | H31: =SUM($C$25:$D$25)/12*$B31 -> 0 | I31: =SUM($C$25:$D$25)/12*$B31 -> 0 | J31: =SUM($C$25:$D$25)/12*$B31 -> 0 | K31: =SUM($C$25:$D$25)/12*$B31 -> 0 | L31: =SUM($C$25:$D$25)/12*$B31 -> 0 | M31: =SUM($C$25:$D$25)/12*$B31 -> 0 | N31: =SUM($C$25:$D$25)/12*$B31 -> 0 | ... R31: =SUM($C$25:$D$25)/12*$B31 -> 0 | S31: =SUM(G31:R31) -> 0
A32: B2B | B32: 0 | G32: =SUM($C$25:$D$25)/12*$B32 -> 0 | H32: =SUM($C$25:$D$25)/12*$B32 -> 0 | I32: =SUM($C$25:$D$25)/12*$B32 -> 0 | J32: =SUM($C$25:$D$25)/12*$B32 -> 0 | K32: =SUM($C$25:$D$25)/12*$B32 -> 0 | L32: =SUM($C$25:$D$25)/12*$B32 -> 0 | M32: =SUM($C$25:$D$25)/12*$B32 -> 0 | N32: =SUM($C$25:$D$25)/12*$B32 -> 0 | ... R32: =SUM($C$25:$D$25)/12*$B32 -> 0 | S32: =SUM(G32:R32) -> 0
A33: Total | G33: =SUM(G26:G32) -> 2851.2 | H33: =SUM(H26:H32) -> 2851.2 | I33: =SUM(I26:I32) -> 2851.2 | J33: =SUM(J26:J32) -> 2851.2 | K33: =SUM(K26:K32) -> 2851.2 | L33: =SUM(L26:L32) -> 2851.2 | M33: =SUM(M26:M32) -> 2851.2 | N33: =SUM(N26:N32) -> 2851.2 | ... S33: =SUM(S26:S32) -> 34214.4
A35: PSM Recharge | B35: 0.2 | G35: =SUM($C$25:$D$25)/12*$B35 -> 712.8 | H35: =SUM($C$25:$D$25)/12*$B35 -> 712.8 | I35: =SUM($C$25:$D$25)/12*$B35 -> 712.8 | J35: =SUM($C$25:$D$25)/12*$B35 -> 712.8 | K35: =SUM($C$25:$D$25)/12*$B35 -> 712.8 | L35: =SUM($C$25:$D$25)/12*$B35 -> 712.8 | M35: =SUM($C$25:$D$25)/12*$B35 -> 712.8 | N35: =SUM($C$25:$D$25)/12*$B35 -> 712.8 | ... R35: =SUM($C$25:$D$25)/12*$B35 -> 712.8 | S35: =SUM(G35:R35) -> 8553.6
A37: Nick Bond | C37: 50000 | D37: =C37*0.188 -> 9400 | E37: =4000*12 -> 48000
A38: Facebook | B38: 0.1 | G38: =SUM($C$37:$D$37)/12*$B38 -> 495 | H38: =SUM($C$37:$D$37)/12*$B38 -> 495 | I38: =SUM($C$37:$D$37)/12*$B38 -> 495 | J38: =SUM($C$37:$D$37)/12*$B38 -> 495 | K38: =SUM($C$37:$D$37)/12*$B38 -> 495 | L38: =SUM($E$37)/12*$B38 -> 400 | M38: =SUM($E$37)/12*$B38 -> 400 | N38: =SUM($E$37)/12*$B38 -> 400 | O38: =SUM($E$37)/12*$B38 -> 400 | P38: =SUM($E$37)/12*$B38 -> 400 | Q38: =SUM($E$37)/12*$B38 -> 400 | R38: =SUM($E$37)/12*$B38 -> 400 | S38: =SUM(G38:R38) -> 5275
A39: Magazine | B39: 0.5 | G39: =SUM($C$37:$D$37)/12*$B39 -> 2475 | H39: =SUM($C$37:$D$37)/12*$B39 -> 2475 | I39: =SUM($C$37:$D$37)/12*$B39 -> 2475 | J39: =SUM($C$37:$D$37)/12*$B39 -> 2475 | K39: =SUM($C$37:$D$37)/12*$B39 -> 2475 | L39: =SUM($E$37)/12*$B39 -> 2000 | M39: =SUM($E$37)/12*$B39 -> 2000 | N39: =SUM($E$37)/12*$B39 -> 2000 | O39: =SUM($E$37)/12*$B39 -> 2000 | P39: =SUM($E$37)/12*$B39 -> 2000 | Q39: =SUM($E$37)/12*$B39 -> 2000 | R39: =SUM($E$37)/12*$B39 -> 2000 | S39: =SUM(G39:R39) -> 26375
A40: Youtube | G40: =SUM($C$37:$D$37)/12*$B40 -> 0 | H40: =SUM($C$37:$D$37)/12*$B40 -> 0 | I40: =SUM($C$37:$D$37)/12*$B40 -> 0 | J40: =SUM($C$37:$D$37)/12*$B40 -> 0 | K40: =SUM($C$37:$D$37)/12*$B40 -> 0 | L40: =SUM($E$37)/12*$B40 -> 0 | M40: =SUM($E$37)/12*$B40 -> 0 | N40: =SUM($E$37)/12*$B40 -> 0 | O40: =SUM($E$37)/12*$B40 -> 0 | P40: =SUM($E$37)/12*$B40 -> 0 | Q40: =SUM($E$37)/12*$B40 -> 0 | R40: =SUM($E$37)/12*$B40 -> 0 | S40: =SUM(G40:R40) -> 0
A41: Instagram | B41: 0.1 | G41: =SUM($C$37:$D$37)/12*$B41 -> 495 | H41: =SUM($C$37:$D$37)/12*$B41 -> 495 | I41: =SUM($C$37:$D$37)/12*$B41 -> 495 | J41: =SUM($C$37:$D$37)/12*$B41 -> 495 | K41: =SUM($C$37:$D$37)/12*$B41 -> 495 | L41: =SUM($E$37)/12*$B41 -> 400 | M41: =SUM($E$37)/12*$B41 -> 400 | N41: =SUM($E$37)/12*$B41 -> 400 | O41: =SUM($E$37)/12*$B41 -> 400 | P41: =SUM($E$37)/12*$B41 -> 400 | Q41: =SUM($E$37)/12*$B41 -> 400 | R41: =SUM($E$37)/12*$B41 -> 400 | S41: =SUM(G41:R41) -> 5275
A42: TikTok | B42: 0.1 | G42: =SUM($C$37:$D$37)/12*$B42 -> 495 | H42: =SUM($C$37:$D$37)/12*$B42 -> 495 | I42: =SUM($C$37:$D$37)/12*$B42 -> 495 | J42: =SUM($C$37:$D$37)/12*$B42 -> 495 | K42: =SUM($C$37:$D$37)/12*$B42 -> 495 | L42: =SUM($E$37)/12*$B42 -> 400 | M42: =SUM($E$37)/12*$B42 -> 400 | N42: =SUM($E$37)/12*$B42 -> 400 | O42: =SUM($E$37)/12*$B42 -> 400 | P42: =SUM($E$37)/12*$B42 -> 400 | Q42: =SUM($E$37)/12*$B42 -> 400 | R42: =SUM($E$37)/12*$B42 -> 400 | S42: =SUM(G42:R42) -> 5275
A43: X | G43: =SUM($C$37:$D$37)/12*$B43 -> 0 | H43: =SUM($C$37:$D$37)/12*$B43 -> 0 | I43: =SUM($C$37:$D$37)/12*$B43 -> 0 | J43: =SUM($C$37:$D$37)/12*$B43 -> 0 | K43: =SUM($C$37:$D$37)/12*$B43 -> 0 | L43: =SUM($E$37)/12*$B43 -> 0 | M43: =SUM($E$37)/12*$B43 -> 0 | N43: =SUM($E$37)/12*$B43 -> 0 | O43: =SUM($E$37)/12*$B43 -> 0 | P43: =SUM($E$37)/12*$B43 -> 0 | Q43: =SUM($E$37)/12*$B43 -> 0 | R43: =SUM($E$37)/12*$B43 -> 0 | S43: =SUM(G43:R43) -> 0
A44: B2B | G44: =SUM($C$37:$D$37)/12*$B44 -> 0 | H44: =SUM($C$37:$D$37)/12*$B44 -> 0 | I44: =SUM($C$37:$D$37)/12*$B44 -> 0 | J44: =SUM($C$37:$D$37)/12*$B44 -> 0 | K44: =SUM($C$37:$D$37)/12*$B44 -> 0 | L44: =SUM($E$37)/12*$B44 -> 0 | M44: =SUM($E$37)/12*$B44 -> 0 | N44: =SUM($E$37)/12*$B44 -> 0 | O44: =SUM($E$37)/12*$B44 -> 0 | P44: =SUM($E$37)/12*$B44 -> 0 | Q44: =SUM($E$37)/12*$B44 -> 0 | R44: =SUM($E$37)/12*$B44 -> 0 | S44: =SUM(G44:R44) -> 0
...

Sheet M1 Freelancers
C1: Actuals | D1: Actuals | E1: Forecast | F1: Forecast | G1: Forecast | H1: Forecast | I1: Forecast | J1: Forecast | K1: Forecast | L1: Forecast | M1: Forecast | N1: Forecast
A2: Employee Name | B2: Allocation | C2: 45931 | D2: 45962 | E2: 45992 | F2: 46023 | G2: 46054 | H2: 46082 | I2: 46113 | J2: 46143 | K2: 46174 | L2: 46204 | M2: 46235 | N2: 46266 | O2: FY26
B3: =12000/12 -> 1000
A5: Facebook | B5: 0.3 | C5: =$B$3*$B5 -> 300 | D5: =$B$3*$B5 -> 300 | E5: =$B$3*$B5 -> 300 | F5: =$B$3*$B5 -> 300 | G5: =$B$3*$B5 -> 300 | H5: =$B$3*$B5 -> 300 | I5: =$B$3*$B5 -> 300 | J5: =$B$3*$B5 -> 300 | ... N5: =$B$3*$B5 -> 300 | O5: =SUM(C5:N5) -> 3600
A6: Instagram | B6: 0.3 | C6: =$B$3*$B6 -> 300 | D6: =$B$3*$B6 -> 300 | E6: =$B$3*$B6 -> 300 | F6: =$B$3*$B6 -> 300 | G6: =$B$3*$B6 -> 300 | H6: =$B$3*$B6 -> 300 | I6: =$B$3*$B6 -> 300 | J6: =$B$3*$B6 -> 300 | ... N6: =$B$3*$B6 -> 300 | O6: =SUM(C6:N6) -> 3600
A7: TikTok | B7: =0.4/3 -> 0.13333333 | C7: =$B$3*$B7 -> 133.33333 | D7: =$B$3*$B7 -> 133.33333 | E7: =$B$3*$B7 -> 133.33333 | F7: =$B$3*$B7 -> 133.33333 | G7: =$B$3*$B7 -> 133.33333 | H7: =$B$3*$B7 -> 133.33333 | I7: =$B$3*$B7 -> 133.33333 | J7: =$B$3*$B7 -> 133.33333 | ... N7: =$B$3*$B7 -> 133.33333 | O7: =SUM(C7:N7) -> 1600
A8: Youtube | B8: =0.4/3 -> 0.13333333 | C8: =$B$3*$B8 -> 133.33333 | D8: =$B$3*$B8 -> 133.33333 | E8: =$B$3*$B8 -> 133.33333 | F8: =$B$3*$B8 -> 133.33333 | G8: =$B$3*$B8 -> 133.33333 | H8: =$B$3*$B8 -> 133.33333 | I8: =$B$3*$B8 -> 133.33333 | J8: =$B$3*$B8 -> 133.33333 | ... N8: =$B$3*$B8 -> 133.33333 | O8: =SUM(C8:N8) -> 1600
A9: X | B9: =0.4/3 -> 0.13333333 | C9: =$B$3*$B9 -> 133.33333 | D9: =$B$3*$B9 -> 133.33333 | E9: =$B$3*$B9 -> 133.33333 | F9: =$B$3*$B9 -> 133.33333 | G9: =$B$3*$B9 -> 133.33333 | H9: =$B$3*$B9 -> 133.33333 | I9: =$B$3*$B9 -> 133.33333 | J9: =$B$3*$B9 -> 133.33333 | ... N9: =$B$3*$B9 -> 133.33333 | O9: =SUM(C9:N9) -> 1600
A11: Total | C11: =SUM(C5:C10) -> 1000 | D11: =SUM(D5:D10) -> 1000 | E11: =SUM(E5:E10) -> 1000 | F11: =SUM(F5:F10) -> 1000 | G11: =SUM(G5:G10) -> 1000 | H11: =SUM(H5:H10) -> 1000 | I11: =SUM(I5:I10) -> 1000 | J11: =SUM(J5:J10) -> 1000 | ... O11: =SUM(O5:O10) -> 12000

Sheet M2 Staff costs 
C1: Current | E1: Proposed | G1: Actuals | H1: Actuals | I1: Forecast | J1: Forecast | K1: Forecast | L1: Forecast | M1: Forecast | N1: Forecast | O1: Forecast | P1: Forecast | Q1: Forecast | R1: Forecast
A2: Employee Name | B2: Allocation | C2: Gross Salary | D2: NI + Pension | E2: Bonus | F2: NI + Pension | G2: 45931 | H2: 45962 | I2: 45992 | J2: 46023 | K2: 46054 | L2: 46082 | M2: 46113 | N2: 46143 | O2: 46174 | P2: 46204 | Q2: 46235 | R2: 46266 | S2: FY26
A3: Ryan Elliot | C3: 38000 | D3: =C3*0.188 -> 7144 | E3: 2000 | F3: =E3*0.188 -> 376
A4: Facebook | B4: 0.25 | G4: =SUM($C$3:$D$3)/12*$B4 -> 940.5 | H4: =SUM($C$3:$D$3)/12*$B4 -> 940.5 | I4: =SUM($C$3:$D$3)/12*$B4 -> 940.5 | J4: =SUM($C$3:$D$3)/12*$B4+SUM($E$3:$F$3)*$B4 -> 1534.5 | K4: =SUM($C$3:$D$3)/12*$B4 -> 940.5 | L4: =SUM($C$3:$D$3)/12*$B4 -> 940.5 | M4: =SUM($C$3:$D$3)/12*$B4 -> 940.5 | N4: =SUM($C$3:$D$3)/12*$B4 -> 940.5 | O4: =SUM($C$3:$D$3)/12*$B4 -> 940.5 | P4: =SUM($C$3:$D$3)/12*$B4 -> 940.5 | Q4: =SUM($C$3:$D$3)/12*$B4 -> 940.5 | R4: =SUM($C$3:$D$3)/12*$B4 -> 940.5 | S4: =SUM(G4:R4) -> 11880
A5: Magazine | B5: 0.025 | G5: =SUM($C$3:$D$3)/12*$B5 -> 94.05 | H5: =SUM($C$3:$D$3)/12*$B5 -> 94.05 | I5: =SUM($C$3:$D$3)/12*$B5 -> 94.05 | J5: =SUM($C$3:$D$3)/12*$B5+SUM($E$3:$F$3)*$B5 -> 153.45 | K5: =SUM($C$3:$D$3)/12*$B5 -> 94.05 | L5: =SUM($C$3:$D$3)/12*$B5 -> 94.05 | M5: =SUM($C$3:$D$3)/12*$B5 -> 94.05 | N5: =SUM($C$3:$D$3)/12*$B5 -> 94.05 | O5: =SUM($C$3:$D$3)/12*$B5 -> 94.05 | P5: =SUM($C$3:$D$3)/12*$B5 -> 94.05 | Q5: =SUM($C$3:$D$3)/12*$B5 -> 94.05 | R5: =SUM($C$3:$D$3)/12*$B5 -> 94.05 | S5: =SUM(G5:R5) -> 1188
A6: Youtube | B6: 0.25 | G6: =SUM($C$3:$D$3)/12*$B6 -> 940.5 | H6: =SUM($C$3:$D$3)/12*$B6 -> 940.5 | I6: =SUM($C$3:$D$3)/12*$B6 -> 940.5 | J6: =SUM($C$3:$D$3)/12*$B6+SUM($E$3:$F$3)*$B6 -> 1534.5 | K6: =SUM($C$3:$D$3)/12*$B6 -> 940.5 | L6: =SUM($C$3:$D$3)/12*$B6 -> 940.5 | M6: =SUM($C$3:$D$3)/12*$B6 -> 940.5 | N6: =SUM($C$3:$D$3)/12*$B6 -> 940.5 | O6: =SUM($C$3:$D$3)/12*$B6 -> 940.5 | P6: =SUM($C$3:$D$3)/12*$B6 -> 940.5 | Q6: =SUM($C$3:$D$3)/12*$B6 -> 940.5 | R6: =SUM($C$3:$D$3)/12*$B6 -> 940.5 | S6: =SUM(G6:R6) -> 11880
A7: Instagram | B7: 0.25 | G7: =SUM($C$3:$D$3)/12*$B7 -> 940.5 | H7: =SUM($C$3:$D$3)/12*$B7 -> 940.5 | I7: =SUM($C$3:$D$3)/12*$B7 -> 940.5 | J7: =SUM($C$3:$D$3)/12*$B7+SUM($E$3:$F$3)*$B7 -> 1534.5 | K7: =SUM($C$3:$D$3)/12*$B7 -> 940.5 | L7: =SUM($C$3:$D$3)/12*$B7 -> 940.5 | M7: =SUM($C$3:$D$3)/12*$B7 -> 940.5 | N7: =SUM($C$3:$D$3)/12*$B7 -> 940.5 | O7: =SUM($C$3:$D$3)/12*$B7 -> 940.5 | P7: =SUM($C$3:$D$3)/12*$B7 -> 940.5 | Q7: =SUM($C$3:$D$3)/12*$B7 -> 940.5 | R7: =SUM($C$3:$D$3)/12*$B7 -> 940.5 | S7: =SUM(G7:R7) -> 11880
A8: TikTok | B8: 0.05 | G8: =SUM($C$3:$D$3)/12*$B8 -> 188.1 | H8: =SUM($C$3:$D$3)/12*$B8 -> 188.1 | I8: =SUM($C$3:$D$3)/12*$B8 -> 188.1 | J8: =SUM($C$3:$D$3)/12*$B8+SUM($E$3:$F$3)*$B8 -> 306.9 | K8: =SUM($C$3:$D$3)/12*$B8 -> 188.1 | L8: =SUM($C$3:$D$3)/12*$B8 -> 188.1 | M8: =SUM($C$3:$D$3)/12*$B8 -> 188.1 | N8: =SUM($C$3:$D$3)/12*$B8 -> 188.1 | O8: =SUM($C$3:$D$3)/12*$B8 -> 188.1 | P8: =SUM($C$3:$D$3)/12*$B8 -> 188.1 | Q8: =SUM($C$3:$D$3)/12*$B8 -> 188.1 | R8: =SUM($C$3:$D$3)/12*$B8 -> 188.1 | S8: =SUM(G8:R8) -> 2376
A9: X | B9: 0.1 | G9: =SUM($C$3:$D$3)/12*$B9 -> 376.2 | H9: =SUM($C$3:$D$3)/12*$B9 -> 376.2 | I9: =SUM($C$3:$D$3)/12*$B9 -> 376.2 | J9: =SUM($C$3:$D$3)/12*$B9+SUM($E$3:$F$3)*$B9 -> 613.8 | K9: =SUM($C$3:$D$3)/12*$B9 -> 376.2 | L9: =SUM($C$3:$D$3)/12*$B9 -> 376.2 | M9: =SUM($C$3:$D$3)/12*$B9 -> 376.2 | N9: =SUM($C$3:$D$3)/12*$B9 -> 376.2 | O9: =SUM($C$3:$D$3)/12*$B9 -> 376.2 | P9: =SUM($C$3:$D$3)/12*$B9 -> 376.2 | Q9: =SUM($C$3:$D$3)/12*$B9 -> 376.2 | R9: =SUM($C$3:$D$3)/12*$B9 -> 376.2 | S9: =SUM(G9:R9) -> 4752
A10: B2B | B10: 0.075 | G10: =SUM($C$3:$D$3)/12*$B10 -> 282.15 | H10: =SUM($C$3:$D$3)/12*$B10 -> 282.15 | I10: =SUM($C$3:$D$3)/12*$B10 -> 282.15 | J10: =SUM($C$3:$D$3)/12*$B10+SUM($E$3:$F$3)*$B10 -> 460.35 | K10: =SUM($C$3:$D$3)/12*$B10 -> 282.15 | L10: =SUM($C$3:$D$3)/12*$B10 -> 282.15 | M10: =SUM($C$3:$D$3)/12*$B10 -> 282.15 | N10: =SUM($C$3:$D$3)/12*$B10 -> 282.15 | O10: =SUM($C$3:$D$3)/12*$B10 -> 282.15 | P10: =SUM($C$3:$D$3)/12*$B10 -> 282.15 | Q10: =SUM($C$3:$D$3)/12*$B10 -> 282.15 | R10: =SUM($C$3:$D$3)/12*$B10 -> 282.15 | S10: =SUM(G10:R10) -> 3564
A12: Total | G12: =SUM(G4:G11) -> 3762 | H12: =SUM(H4:H11) -> 3762 | I12: =SUM(I4:I11) -> 3762 | J12: =SUM(J4:J11) -> 6138 | K12: =SUM(K4:K11) -> 3762 | L12: =SUM(L4:L11) -> 3762 | M12: =SUM(M4:M11) -> 3762 | N12: =SUM(N4:N11) -> 3762 | ... S12: =SUM(S4:S11) -> 47520
S13: =S12-F3-E3-D3-C3 -> 0
A14: Danny Gilfilen | C14: 25000 | D14: =C14*0.188 -> 4700
A15: Facebook | B15: 0.3 | G15: =SUM($C$14:$D$14)/12*$B15 -> 742.5 | H15: =SUM($C$14:$D$14)/12*$B15 -> 742.5 | I15: =SUM($C$14:$D$14)/12*$B15 -> 742.5 | J15: =SUM($C$14:$D$14)/12*$B15 -> 742.5 | K15: =SUM($C$14:$D$14)/12*$B15 -> 742.5 | L15: =SUM($C$14:$D$14)/12*$B15 -> 742.5 | M15: =SUM($C$14:$D$14)/12*$B15 -> 742.5 | N15: =SUM($C$14:$D$14)/12*$B15 -> 742.5 | ... R15: =SUM($C$14:$D$14)/12*$B15 -> 742.5 | S15: =SUM(G15:R15) -> 8910
A16: Magazine | B16: 0 | G16: =SUM($C$14:$D$14)/12*$B16 -> 0 | H16: =SUM($C$14:$D$14)/12*$B16 -> 0 | I16: =SUM($C$14:$D$14)/12*$B16 -> 0 | J16: =SUM($C$14:$D$14)/12*$B16 -> 0 | K16: =SUM($C$14:$D$14)/12*$B16 -> 0 | L16: =SUM($C$14:$D$14)/12*$B16 -> 0 | M16: =SUM($C$14:$D$14)/12*$B16 -> 0 | N16: =SUM($C$14:$D$14)/12*$B16 -> 0 | ... R16: =SUM($C$14:$D$14)/12*$B16 -> 0 | S16: =SUM(G16:R16) -> 0
A17: Youtube | B17: 0.3 | G17: =SUM($C$14:$D$14)/12*$B17 -> 742.5 | H17: =SUM($C$14:$D$14)/12*$B17 -> 742.5 | I17: =SUM($C$14:$D$14)/12*$B17 -> 742.5 | J17: =SUM($C$14:$D$14)/12*$B17 -> 742.5 | K17: =SUM($C$14:$D$14)/12*$B17 -> 742.5 | L17: =SUM($C$14:$D$14)/12*$B17 -> 742.5 | M17: =SUM($C$14:$D$14)/12*$B17 -> 742.5 | N17: =SUM($C$14:$D$14)/12*$B17 -> 742.5 | ... R17: =SUM($C$14:$D$14)/12*$B17 -> 742.5 | S17: =SUM(G17:R17) -> 8910
A18: Instagram | B18: 0.175 | G18: =SUM($C$14:$D$14)/12*$B18 -> 433.125 | H18: =SUM($C$14:$D$14)/12*$B18 -> 433.125 | I18: =SUM($C$14:$D$14)/12*$B18 -> 433.125 | J18: =SUM($C$14:$D$14)/12*$B18 -> 433.125 | K18: =SUM($C$14:$D$14)/12*$B18 -> 433.125 | L18: =SUM($C$14:$D$14)/12*$B18 -> 433.125 | M18: =SUM($C$14:$D$14)/12*$B18 -> 433.125 | N18: =SUM($C$14:$D$14)/12*$B18 -> 433.125 | ... R18: =SUM($C$14:$D$14)/12*$B18 -> 433.125 | S18: =SUM(G18:R18) -> 5197.5
A19: TikTok | B19: 0.175 | G19: =SUM($C$14:$D$14)/12*$B19 -> 433.125 | H19: =SUM($C$14:$D$14)/12*$B19 -> 433.125 | I19: =SUM($C$14:$D$14)/12*$B19 -> 433.125 | J19: =SUM($C$14:$D$14)/12*$B19 -> 433.125 | K19: =SUM($C$14:$D$14)/12*$B19 -> 433.125 | L19: =SUM($C$14:$D$14)/12*$B19 -> 433.125 | M19: =SUM($C$14:$D$14)/12*$B19 -> 433.125 | N19: =SUM($C$14:$D$14)/12*$B19 -> 433.125 | ... R19: =SUM($C$14:$D$14)/12*$B19 -> 433.125 | S19: =SUM(G19:R19) -> 5197.5
A20: X | B20: 0.05 | G20: =SUM($C$14:$D$14)/12*$B20 -> 123.75 | H20: =SUM($C$14:$D$14)/12*$B20 -> 123.75 | I20: =SUM($C$14:$D$14)/12*$B20 -> 123.75 | J20: =SUM($C$14:$D$14)/12*$B20 -> 123.75 | K20: =SUM($C$14:$D$14)/12*$B20 -> 123.75 | L20: =SUM($C$14:$D$14)/12*$B20 -> 123.75 | M20: =SUM($C$14:$D$14)/12*$B20 -> 123.75 | N20: =SUM($C$14:$D$14)/12*$B20 -> 123.75 | ... R20: =SUM($C$14:$D$14)/12*$B20 -> 123.75 | S20: =SUM(G20:R20) -> 1485
A21: B2B | B21: 0 | G21: =SUM($C$14:$D$14)/12*$B21 -> 0 | H21: =SUM($C$14:$D$14)/12*$B21 -> 0 | I21: =SUM($C$14:$D$14)/12*$B21 -> 0 | J21: =SUM($C$14:$D$14)/12*$B21 -> 0 | K21: =SUM($C$14:$D$14)/12*$B21 -> 0 | L21: =SUM($C$14:$D$14)/12*$B21 -> 0 | M21: =SUM($C$14:$D$14)/12*$B21 -> 0 | N21: =SUM($C$14:$D$14)/12*$B21 -> 0 | ... R21: =SUM($C$14:$D$14)/12*$B21 -> 0 | S21: =SUM(G21:R21) -> 0
A23: Total | G23: =SUM(G15:G22) -> 2475 | H23: =SUM(H15:H22) -> 2475 | I23: =SUM(I15:I22) -> 2475 | J23: =SUM(J15:J22) -> 2475 | K23: =SUM(K15:K22) -> 2475 | L23: =SUM(L15:L22) -> 2475 | M23: =SUM(M15:M22) -> 2475 | N23: =SUM(N15:N22) -> 2475 | ... S23: =SUM(S15:S22) -> 29700
S24: =S23-C14-D14 -> 0
A25: Daniel Greg | B25: Assumes leave in Mar 26 | C25: 36000 | D25: =C25*0.188 -> 6768
A26: Facebook | B26: 0.1 | G26: =SUM($C$25:$D$25)/12*$B26 -> 356.4 | H26: =SUM($C$25:$D$25)/12*$B26 -> 356.4 | I26: =SUM($C$25:$D$25)/12*$B26 -> 356.4 | J26: =SUM($C$25:$D$25)/12*$B26 -> 356.4 | K26: =SUM($C$25:$D$25)/12*$B26 -> 356.4 | S26: =SUM(G26:R26) -> 1782
A27: Magazine | B27: 0 | G27: =SUM($C$25:$D$25)/12*$B27 -> 0 | H27: =SUM($C$25:$D$25)/12*$B27 -> 0 | I27: =SUM($C$25:$D$25)/12*$B27 -> 0 | J27: =SUM($C$25:$D$25)/12*$B27 -> 0 | K27: =SUM($C$25:$D$25)/12*$B27 -> 0 | S27: =SUM(G27:R27) -> 0
A28: Youtube | B28: 0.6 | G28: =SUM($C$25:$D$25)/12*$B28 -> 2138.4 | H28: =SUM($C$25:$D$25)/12*$B28 -> 2138.4 | I28: =SUM($C$25:$D$25)/12*$B28 -> 2138.4 | J28: =SUM($C$25:$D$25)/12*$B28 -> 2138.4 | K28: =SUM($C$25:$D$25)/12*$B28 -> 2138.4 | S28: =SUM(G28:R28) -> 10692
A29: Instagram | B29: 0.05 | G29: =SUM($C$25:$D$25)/12*$B29 -> 178.2 | H29: =SUM($C$25:$D$25)/12*$B29 -> 178.2 | I29: =SUM($C$25:$D$25)/12*$B29 -> 178.2 | J29: =SUM($C$25:$D$25)/12*$B29 -> 178.2 | K29: =SUM($C$25:$D$25)/12*$B29 -> 178.2 | S29: =SUM(G29:R29) -> 891
A30: TikTok | B30: 0.05 | G30: =SUM($C$25:$D$25)/12*$B30 -> 178.2 | H30: =SUM($C$25:$D$25)/12*$B30 -> 178.2 | I30: =SUM($C$25:$D$25)/12*$B30 -> 178.2 | J30: =SUM($C$25:$D$25)/12*$B30 -> 178.2 | K30: =SUM($C$25:$D$25)/12*$B30 -> 178.2 | S30: =SUM(G30:R30) -> 891
A31: X | B31: 0 | G31: =SUM($C$25:$D$25)/12*$B31 -> 0 | H31: =SUM($C$25:$D$25)/12*$B31 -> 0 | I31: =SUM($C$25:$D$25)/12*$B31 -> 0 | J31: =SUM($C$25:$D$25)/12*$B31 -> 0 | K31: =SUM($C$25:$D$25)/12*$B31 -> 0 | S31: =SUM(G31:R31) -> 0
A32: B2B | B32: 0 | G32: =SUM($C$25:$D$25)/12*$B32 -> 0 | H32: =SUM($C$25:$D$25)/12*$B32 -> 0 | I32: =SUM($C$25:$D$25)/12*$B32 -> 0 | J32: =SUM($C$25:$D$25)/12*$B32 -> 0 | K32: =SUM($C$25:$D$25)/12*$B32 -> 0 | S32: =SUM(G32:R32) -> 0
A33: Total | G33: =SUM(G26:G32) -> 2851.2 | H33: =SUM(H26:H32) -> 2851.2 | I33: =SUM(I26:I32) -> 2851.2 | J33: =SUM(J26:J32) -> 2851.2 | K33: =SUM(K26:K32) -> 2851.2 | L33: =SUM(L26:L32) -> 0 | M33: =SUM(M26:M32) -> 0 | N33: =SUM(N26:N32) -> 0 | ... S33: =SUM(S26:S32) -> 14256
A35: PSM Recharge | B35: 0.2 | G35: =SUM($C$25:$D$25)/12*$B35 -> 712.8 | H35: =SUM($C$25:$D$25)/12*$B35 -> 712.8 | I35: =SUM($C$25:$D$25)/12*$B35 -> 712.8 | J35: =SUM($C$25:$D$25)/12*$B35 -> 712.8 | K35: =SUM($C$25:$D$25)/12*$B35 -> 712.8 | S35: =SUM(G35:R35) -> 3564
A37: Nick Bond | C37: 50000 | D37: =C37*0.188 -> 9400 | E37: =4000*12 -> 48000
A38: Facebook | B38: 0.1 | G38: =SUM($C$37:$D$37)/12*$B38 -> 495 | H38: =SUM($C$37:$D$37)/12*$B38 -> 495 | I38: =SUM($C$37:$D$37)/12*$B38 -> 495 | J38: =SUM($C$37:$D$37)/12*$B38 -> 495 | K38: =SUM($C$37:$D$37)/12*$B38 -> 495 | L38: =SUM($E$37)/12*$B38 -> 400 | M38: =SUM($E$37)/12*$B38 -> 400 | N38: =SUM($E$37)/12*$B38 -> 400 | O38: =SUM($E$37)/12*$B38 -> 400 | P38: =SUM($E$37)/12*$B38 -> 400 | Q38: =SUM($E$37)/12*$B38 -> 400 | R38: =SUM($E$37)/12*$B38 -> 400 | S38: =SUM(G38:R38) -> 5275
A39: Magazine | B39: 0.5 | G39: =SUM($C$37:$D$37)/12*$B39 -> 2475 | H39: =SUM($C$37:$D$37)/12*$B39 -> 2475 | I39: =SUM($C$37:$D$37)/12*$B39 -> 2475 | J39: =SUM($C$37:$D$37)/12*$B39 -> 2475 | K39: =SUM($C$37:$D$37)/12*$B39 -> 2475 | L39: =SUM($E$37)/12*$B39 -> 2000 | M39: =SUM($E$37)/12*$B39 -> 2000 | N39: =SUM($E$37)/12*$B39 -> 2000 | O39: =SUM($E$37)/12*$B39 -> 2000 | P39: =SUM($E$37)/12*$B39 -> 2000 | Q39: =SUM($E$37)/12*$B39 -> 2000 | R39: =SUM($E$37)/12*$B39 -> 2000 | S39: =SUM(G39:R39) -> 26375
A40: Youtube | G40: =SUM($C$37:$D$37)/12*$B40 -> 0 | H40: =SUM($C$37:$D$37)/12*$B40 -> 0 | I40: =SUM($C$37:$D$37)/12*$B40 -> 0 | J40: =SUM($C$37:$D$37)/12*$B40 -> 0 | K40: =SUM($C$37:$D$37)/12*$B40 -> 0 | L40: =SUM($E$37)/12*$B40 -> 0 | M40: =SUM($E$37)/12*$B40 -> 0 | N40: =SUM($E$37)/12*$B40 -> 0 | O40: =SUM($E$37)/12*$B40 -> 0 | P40: =SUM($E$37)/12*$B40 -> 0 | Q40: =SUM($E$37)/12*$B40 -> 0 | R40: =SUM($E$37)/12*$B40 -> 0 | S40: =SUM(G40:R40) -> 0
A41: Instagram | B41: 0.1 | G41: =SUM($C$37:$D$37)/12*$B41 -> 495 | H41: =SUM($C$37:$D$37)/12*$B41 -> 495 | I41: =SUM($C$37:$D$37)/12*$B41 -> 495 | J41: =SUM($C$37:$D$37)/12*$B41 -> 495 | K41: =SUM($C$37:$D$37)/12*$B41 -> 495 | L41: =SUM($E$37)/12*$B41 -> 400 | M41: =SUM($E$37)/12*$B41 -> 400 | N41: =SUM($E$37)/12*$B41 -> 400 | O41: =SUM($E$37)/12*$B41 -> 400 | P41: =SUM($E$37)/12*$B41 -> 400 | Q41: =SUM($E$37)/12*$B41 -> 400 | R41: =SUM($E$37)/12*$B41 -> 400 | S41: =SUM(G41:R41) -> 5275
A42: TikTok | B42: 0.1 | G42: =SUM($C$37:$D$37)/12*$B42 -> 495 | H42: =SUM($C$37:$D$37)/12*$B42 -> 495 | I42: =SUM($C$37:$D$37)/12*$B42 -> 495 | J42: =SUM($C$37:$D$37)/12*$B42 -> 495 | K42: =SUM($C$37:$D$37)/12*$B42 -> 495 | L42: =SUM($E$37)/12*$B42 -> 400 | M42: =SUM($E$37)/12*$B42 -> 400 | N42: =SUM($E$37)/12*$B42 -> 400 | O42: =SUM($E$37)/12*$B42 -> 400 | P42: =SUM($E$37)/12*$B42 -> 400 | Q42: =SUM($E$37)/12*$B42 -> 400 | R42: =SUM($E$37)/12*$B42 -> 400 | S42: =SUM(G42:R42) -> 5275
A43: X | G43: =SUM($C$37:$D$37)/12*$B43 -> 0 | H43: =SUM($C$37:$D$37)/12*$B43 -> 0 | I43: =SUM($C$37:$D$37)/12*$B43 -> 0 | J43: =SUM($C$37:$D$37)/12*$B43 -> 0 | K43: =SUM($C$37:$D$37)/12*$B43 -> 0 | L43: =SUM($E$37)/12*$B43 -> 0 | M43: =SUM($E$37)/12*$B43 -> 0 | N43: =SUM($E$37)/12*$B43 -> 0 | O43: =SUM($E$37)/12*$B43 -> 0 | P43: =SUM($E$37)/12*$B43 -> 0 | Q43: =SUM($E$37)/12*$B43 -> 0 | R43: =SUM($E$37)/12*$B43 -> 0 | S43: =SUM(G43:R43) -> 0
A44: B2B | G44: =SUM($C$37:$D$37)/12*$B44 -> 0 | H44: =SUM($C$37:$D$37)/12*$B44 -> 0 | I44: =SUM($C$37:$D$37)/12*$B44 -> 0 | J44: =SUM($C$37:$D$37)/12*$B44 -> 0 | K44: =SUM($C$37:$D$37)/12*$B44 -> 0 | L44: =SUM($E$37)/12*$B44 -> 0 | M44: =SUM($E$37)/12*$B44 -> 0 | N44: =SUM($E$37)/12*$B44 -> 0 | O44: =SUM($E$37)/12*$B44 -> 0 | P44: =SUM($E$37)/12*$B44 -> 0 | Q44: =SUM($E$37)/12*$B44 -> 0 | R44: =SUM($E$37)/12*$B44 -> 0 | S44: =SUM(G44:R44) -> 0
...

Sheet M2 Freelancers
C1: Actuals | D1: Actuals | E1: Forecast | F1: Forecast | G1: Forecast | H1: Forecast | I1: Forecast | J1: Forecast | K1: Forecast | L1: Forecast | M1: Forecast | N1: Forecast
A2: Employee Name | B2: Allocation | C2: 45931 | D2: 45962 | E2: 45992 | F2: 46023 | G2: 46054 | H2: 46082 | I2: 46113 | J2: 46143 | K2: 46174 | L2: 46204 | M2: 46235 | N2: 46266 | O2: FY26
B3: =30000/12 -> 2500
A5: Facebook | B5: =0.5/3 -> 0.16666667 | I5: =$B$3*$B5 -> 416.66667 | J5: =$B$3*$B5 -> 416.66667 | K5: =$B$3*$B5 -> 416.66667 | L5: =$B$3*$B5 -> 416.66667 | M5: =$B$3*$B5 -> 416.66667 | N5: =$B$3*$B5 -> 416.66667 | O5: =SUM(C5:N5) -> 2500
A6: Instagram | B6: =0.5/3 -> 0.16666667 | I6: =$B$3*$B6 -> 416.66667 | J6: =$B$3*$B6 -> 416.66667 | K6: =$B$3*$B6 -> 416.66667 | L6: =$B$3*$B6 -> 416.66667 | M6: =$B$3*$B6 -> 416.66667 | N6: =$B$3*$B6 -> 416.66667 | O6: =SUM(C6:N6) -> 2500
A7: TikTok | B7: =0.5/3 -> 0.16666667 | I7: =$B$3*$B7 -> 416.66667 | J7: =$B$3*$B7 -> 416.66667 | K7: =$B$3*$B7 -> 416.66667 | L7: =$B$3*$B7 -> 416.66667 | M7: =$B$3*$B7 -> 416.66667 | N7: =$B$3*$B7 -> 416.66667 | O7: =SUM(C7:N7) -> 2500
A8: Youtube | B8: 0.5 | I8: =$B$3*$B8 -> 1250 | J8: =$B$3*$B8 -> 1250 | K8: =$B$3*$B8 -> 1250 | L8: =$B$3*$B8 -> 1250 | M8: =$B$3*$B8 -> 1250 | N8: =$B$3*$B8 -> 1250 | O8: =SUM(C8:N8) -> 7500
A10: Total | C10: =SUM(C5:C9) -> 0 | D10: =SUM(D5:D9) -> 0 | E10: =SUM(E5:E9) -> 0 | F10: =SUM(F5:F9) -> 0 | G10: =SUM(G5:G9) -> 0 | H10: =SUM(H5:H9) -> 0 | I10: =SUM(I5:I9) -> 2500 | J10: =SUM(J5:J9) -> 2500 | ... O10: =SUM(O5:O9) -> 15000

Sheet M3 Staff costs
C1: Current | E1: Proposed | G1: Actuals | H1: Actuals | I1: Forecast | J1: Forecast | K1: Forecast | L1: Forecast | M1: Forecast | N1: Forecast | O1: Forecast | P1: Forecast | Q1: Forecast | R1: Forecast
A2: Employee Name | B2: Allocation | C2: Gross Salary | D2: NI + Pension | E2: Bonus | F2: NI + Pension | G2: 45931 | H2: 45962 | I2: 45992 | J2: 46023 | K2: 46054 | L2: 46082 | M2: 46113 | N2: 46143 | O2: 46174 | P2: 46204 | Q2: 46235 | R2: 46266 | S2: FY26
A3: Ryan Elliot | C3: 38000 | D3: =C3*0.188 -> 7144 | E3: 2000 | F3: =E3*0.188 -> 376
A4: Facebook | B4: 0.25 | G4: =SUM($C$3:$D$3)/12*$B4 -> 940.5 | H4: =SUM($C$3:$D$3)/12*$B4 -> 940.5 | I4: =SUM($C$3:$D$3)/12*$B4 -> 940.5 | J4: =SUM($C$3:$D$3)/12*$B4+SUM($E$3:$F$3)*$B4 -> 1534.5 | K4: =SUM($C$3:$D$3)/12*$B4 -> 940.5 | L4: =SUM($C$3:$D$3)/12*$B4 -> 940.5 | M4: =SUM($C$3:$D$3)/12*$B4 -> 940.5 | N4: =SUM($C$3:$D$3)/12*$B4 -> 940.5 | O4: =SUM($C$3:$D$3)/12*$B4 -> 940.5 | P4: =SUM($C$3:$D$3)/12*$B4 -> 940.5 | Q4: =SUM($C$3:$D$3)/12*$B4 -> 940.5 | R4: =SUM($C$3:$D$3)/12*$B4 -> 940.5 | S4: =SUM(G4:R4) -> 11880
A5: Magazine | B5: 0.025 | G5: =SUM($C$3:$D$3)/12*$B5 -> 94.05 | H5: =SUM($C$3:$D$3)/12*$B5 -> 94.05 | I5: =SUM($C$3:$D$3)/12*$B5 -> 94.05 | J5: =SUM($C$3:$D$3)/12*$B5+SUM($E$3:$F$3)*$B5 -> 153.45 | K5: =SUM($C$3:$D$3)/12*$B5 -> 94.05 | L5: =SUM($C$3:$D$3)/12*$B5 -> 94.05 | M5: =SUM($C$3:$D$3)/12*$B5 -> 94.05 | N5: =SUM($C$3:$D$3)/12*$B5 -> 94.05 | O5: =SUM($C$3:$D$3)/12*$B5 -> 94.05 | P5: =SUM($C$3:$D$3)/12*$B5 -> 94.05 | Q5: =SUM($C$3:$D$3)/12*$B5 -> 94.05 | R5: =SUM($C$3:$D$3)/12*$B5 -> 94.05 | S5: =SUM(G5:R5) -> 1188
A6: Youtube | B6: 0.25 | G6: =SUM($C$3:$D$3)/12*$B6 -> 940.5 | H6: =SUM($C$3:$D$3)/12*$B6 -> 940.5 | I6: =SUM($C$3:$D$3)/12*$B6 -> 940.5 | J6: =SUM($C$3:$D$3)/12*$B6+SUM($E$3:$F$3)*$B6 -> 1534.5 | K6: =SUM($C$3:$D$3)/12*$B6 -> 940.5 | L6: =SUM($C$3:$D$3)/12*$B6 -> 940.5 | M6: =SUM($C$3:$D$3)/12*$B6 -> 940.5 | N6: =SUM($C$3:$D$3)/12*$B6 -> 940.5 | O6: =SUM($C$3:$D$3)/12*$B6 -> 940.5 | P6: =SUM($C$3:$D$3)/12*$B6 -> 940.5 | Q6: =SUM($C$3:$D$3)/12*$B6 -> 940.5 | R6: =SUM($C$3:$D$3)/12*$B6 -> 940.5 | S6: =SUM(G6:R6) -> 11880
A7: Instagram | B7: 0.25 | G7: =SUM($C$3:$D$3)/12*$B7 -> 940.5 | H7: =SUM($C$3:$D$3)/12*$B7 -> 940.5 | I7: =SUM($C$3:$D$3)/12*$B7 -> 940.5 | J7: =SUM($C$3:$D$3)/12*$B7+SUM($E$3:$F$3)*$B7 -> 1534.5 | K7: =SUM($C$3:$D$3)/12*$B7 -> 940.5 | L7: =SUM($C$3:$D$3)/12*$B7 -> 940.5 | M7: =SUM($C$3:$D$3)/12*$B7 -> 940.5 | N7: =SUM($C$3:$D$3)/12*$B7 -> 940.5 | O7: =SUM($C$3:$D$3)/12*$B7 -> 940.5 | P7: =SUM($C$3:$D$3)/12*$B7 -> 940.5 | Q7: =SUM($C$3:$D$3)/12*$B7 -> 940.5 | R7: =SUM($C$3:$D$3)/12*$B7 -> 940.5 | S7: =SUM(G7:R7) -> 11880
A8: TikTok | B8: 0.05 | G8: =SUM($C$3:$D$3)/12*$B8 -> 188.1 | H8: =SUM($C$3:$D$3)/12*$B8 -> 188.1 | I8: =SUM($C$3:$D$3)/12*$B8 -> 188.1 | J8: =SUM($C$3:$D$3)/12*$B8+SUM($E$3:$F$3)*$B8 -> 306.9 | K8: =SUM($C$3:$D$3)/12*$B8 -> 188.1 | L8: =SUM($C$3:$D$3)/12*$B8 -> 188.1 | M8: =SUM($C$3:$D$3)/12*$B8 -> 188.1 | N8: =SUM($C$3:$D$3)/12*$B8 -> 188.1 | O8: =SUM($C$3:$D$3)/12*$B8 -> 188.1 | P8: =SUM($C$3:$D$3)/12*$B8 -> 188.1 | Q8: =SUM($C$3:$D$3)/12*$B8 -> 188.1 | R8: =SUM($C$3:$D$3)/12*$B8 -> 188.1 | S8: =SUM(G8:R8) -> 2376
A9: X | B9: 0.1 | G9: =SUM($C$3:$D$3)/12*$B9 -> 376.2 | H9: =SUM($C$3:$D$3)/12*$B9 -> 376.2 | I9: =SUM($C$3:$D$3)/12*$B9 -> 376.2 | J9: =SUM($C$3:$D$3)/12*$B9+SUM($E$3:$F$3)*$B9 -> 613.8 | K9: =SUM($C$3:$D$3)/12*$B9 -> 376.2 | L9: =SUM($C$3:$D$3)/12*$B9 -> 376.2 | M9: =SUM($C$3:$D$3)/12*$B9 -> 376.2 | N9: =SUM($C$3:$D$3)/12*$B9 -> 376.2 | O9: =SUM($C$3:$D$3)/12*$B9 -> 376.2 | P9: =SUM($C$3:$D$3)/12*$B9 -> 376.2 | Q9: =SUM($C$3:$D$3)/12*$B9 -> 376.2 | R9: =SUM($C$3:$D$3)/12*$B9 -> 376.2 | S9: =SUM(G9:R9) -> 4752
A10: B2B | B10: 0.075 | G10: =SUM($C$3:$D$3)/12*$B10 -> 282.15 | H10: =SUM($C$3:$D$3)/12*$B10 -> 282.15 | I10: =SUM($C$3:$D$3)/12*$B10 -> 282.15 | J10: =SUM($C$3:$D$3)/12*$B10+SUM($E$3:$F$3)*$B10 -> 460.35 | K10: =SUM($C$3:$D$3)/12*$B10 -> 282.15 | L10: =SUM($C$3:$D$3)/12*$B10 -> 282.15 | M10: =SUM($C$3:$D$3)/12*$B10 -> 282.15 | N10: =SUM($C$3:$D$3)/12*$B10 -> 282.15 | O10: =SUM($C$3:$D$3)/12*$B10 -> 282.15 | P10: =SUM($C$3:$D$3)/12*$B10 -> 282.15 | Q10: =SUM($C$3:$D$3)/12*$B10 -> 282.15 | R10: =SUM($C$3:$D$3)/12*$B10 -> 282.15 | S10: =SUM(G10:R10) -> 3564
A12: Total | G12: =SUM(G4:G11) -> 3762 | H12: =SUM(H4:H11) -> 3762 | I12: =SUM(I4:I11) -> 3762 | J12: =SUM(J4:J11) -> 6138 | K12: =SUM(K4:K11) -> 3762 | L12: =SUM(L4:L11) -> 3762 | M12: =SUM(M4:M11) -> 3762 | N12: =SUM(N4:N11) -> 3762 | ... S12: =SUM(S4:S11) -> 47520
S13: =S12-F3-E3-D3-C3 -> 0
A14: Danny Gilfilen | C14: 25000 | D14: =C14*0.188 -> 4700
A15: Facebook | B15: 0.3 | G15: =SUM($C$14:$D$14)/12*$B15 -> 742.5 | H15: =SUM($C$14:$D$14)/12*$B15 -> 742.5 | I15: =SUM($C$14:$D$14)/12*$B15 -> 742.5 | J15: =SUM($C$14:$D$14)/12*$B15 -> 742.5 | K15: =SUM($C$14:$D$14)/12*$B15 -> 742.5 | L15: =SUM($C$14:$D$14)/12*$B15 -> 742.5 | M15: =SUM($C$14:$D$14)/12*$B15 -> 742.5 | N15: =SUM($C$14:$D$14)/12*$B15 -> 742.5 | ... R15: =SUM($C$14:$D$14)/12*$B15 -> 742.5 | S15: =SUM(G15:R15) -> 8910
A16: Magazine | B16: 0 | G16: =SUM($C$14:$D$14)/12*$B16 -> 0 | H16: =SUM($C$14:$D$14)/12*$B16 -> 0 | I16: =SUM($C$14:$D$14)/12*$B16 -> 0 | J16: =SUM($C$14:$D$14)/12*$B16 -> 0 | K16: =SUM($C$14:$D$14)/12*$B16 -> 0 | L16: =SUM($C$14:$D$14)/12*$B16 -> 0 | M16: =SUM($C$14:$D$14)/12*$B16 -> 0 | N16: =SUM($C$14:$D$14)/12*$B16 -> 0 | ... R16: =SUM($C$14:$D$14)/12*$B16 -> 0 | S16: =SUM(G16:R16) -> 0
